Workbook
Name SegmentaçãodeDados_ANO: #N/A
Name SegmentaçãodeDados_CATEGORIA: #N/A
Name SegmentaçãodeDados_ITEM: #N/A
Name SegmentaçãodeDados_MÊS: #N/A
Name SegmentaçãodeDados_RETIRADA: #N/A
Name SegmentaçãodeDados_SEMANA: #N/A
Name Timeline_DATA: #N/A

Sheet BASE
B3: DATA | C3: COMANDA | D3: ID_ITEM | E3: RETIRADA | F3: FORMA DE PAGAMENTO | G3: CATEGORIA | H3: ITEM | I3: QUANTIDADE | J3: TIPO DE VALOR | K3: VALOR | L3: MÊS | M3: SEMANA | N3: ANO
B4: 45013 | C4: 12030 | D4: =COUNTIF(C$4:C4,Tabela3[[#This Row],[COMANDA]]) -> 1 | E4: PRATO | F4: PIX | G4: REFEIÇÃO | H4: Hambúrguer | I4: 1 | J4: PREÇO1 | K4: =INDEX(LISTAS!$H:$Q,MATCH(BASE!H4,LISTAS!$G:$G,0),MATCH(BASE!J4,LISTAS!$H$3:$Q$3,0))*Tabela3[[#This Row],[QUANTIDADE]] -> 14 | L4: =TEXT(Tabela3[[#This Row],[DATA]],"MM") -> 03 | M4: =WEEKNUM(Tabela3[[#This Row],[DATA]]) -> 13 | N4: =YEAR(Tabela3[[#This Row],[DATA]]) -> 2023
B5: 45013 | C5: 12031 | D5: =COUNTIF(C$4:C5,Tabela3[[#This Row],[COMANDA]]) -> 1 | E5: MARMITA | F5: Dinheiro | G5: REFEIÇÃO | H5: Linguiça | I5: 1 | J5: PREÇO1 | K5: =INDEX(LISTAS!$H:$Q,MATCH(BASE!H5,LISTAS!$G:$G,0),MATCH(BASE!J5,LISTAS!$H$3:$Q$3,0))*Tabela3[[#This Row],[QUANTIDADE]] -> 16 | L5: =TEXT(Tabela3[[#This Row],[DATA]],"MM") -> 03 | M5: =WEEKNUM(Tabela3[[#This Row],[DATA]]) -> 13 | N5: =YEAR(Tabela3[[#This Row],[DATA]]) -> 2023
B6: 45013 | C6: 12031 | D6: =COUNTIF(C$4:C6,Tabela3[[#This Row],[COMANDA]]) -> 2 | E6: MARMITA | F6: Dinheiro | G6: BEBIDA | H6: Guaraná lata | I6: 1 | J6: PREÇO1 | K6: =INDEX(LISTAS!$H:$Q,MATCH(BASE!H6,LISTAS!$G:$G,0),MATCH(BASE!J6,LISTAS!$H$3:$Q$3,0))*Tabela3[[#This Row],[QUANTIDADE]] -> 4 | L6: =TEXT(Tabela3[[#This Row],[DATA]],"MM") -> 03 | M6: =WEEKNUM(Tabela3[[#This Row],[DATA]]) -> 13 | N6: =YEAR(Tabela3[[#This Row],[DATA]]) -> 2023
B7: 45013 | C7: 12032 | D7: =COUNTIF(C$4:C7,Tabela3[[#This Row],[COMANDA]]) -> 1 | E7: MARMITA | F7: Débito | G7: REFEIÇÃO | H7: Hambúrguer | I7: 1 | J7: PREÇO1 | K7: =INDEX(LISTAS!$H:$Q,MATCH(BASE!H7,LISTAS!$G:$G,0),MATCH(BASE!J7,LISTAS!$H$3:$Q$3,0))*Tabela3[[#This Row],[QUANTIDADE]] -> 14 | L7: =TEXT(Tabela3[[#This Row],[DATA]],"MM") -> 03 | M7: =WEEKNUM(Tabela3[[#This Row],[DATA]]) -> 13 | N7: =YEAR(Tabela3[[#This Row],[DATA]]) -> 2023
B8: 45013 | C8: 12033 | D8: =COUNTIF(C$4:C8,Tabela3[[#This Row],[COMANDA]]) -> 1 | E8: MARMITA | F8: Débito | G8: REFEIÇÃO | H8: Do dia | I8: 1 | J8: PREÇO1 | K8: =INDEX(LISTAS!$H:$Q,MATCH(BASE!H8,LISTAS!$G:$G,0),MATCH(BASE!J8,LISTAS!$H$3:$Q$3,0))*Tabela3[[#This Row],[QUANTIDADE]] -> 16 | L8: =TEXT(Tabela3[[#This Row],[DATA]],"MM") -> 03 | M8: =WEEKNUM(Tabela3[[#This Row],[DATA]]) -> 13 | N8: =YEAR(Tabela3[[#This Row],[DATA]]) -> 2023
B9: 45013 | C9: 12033 | D9: =COUNTIF(C$4:C9,Tabela3[[#This Row],[COMANDA]]) -> 2 | E9: MARMITA | F9: Débito | G9: ADICIONAIS | H9: Fritas Adicional | I9: 1 | J9: PREÇO1 | K9: =INDEX(LISTAS!$H:$Q,MATCH(BASE!H9,LISTAS!$G:$G,0),MATCH(BASE!J9,LISTAS!$H$3:$Q$3,0))*Tabela3[[#This Row],[QUANTIDADE]] -> 4 | L9: =TEXT(Tabela3[[#This Row],[DATA]],"MM") -> 03 | M9: =WEEKNUM(Tabela3[[#This Row],[DATA]]) -> 13 | N9: =YEAR(Tabela3[[#This Row],[DATA]]) -> 2023
B10: 45013 | C10: 12034 | D10: =COUNTIF(C$4:C10,Tabela3[[#This Row],[COMANDA]]) -> 1 | E10: PRATO | F10: Débito | G10: REFEIÇÃO | H10: Vegetariano | I10: 1 | J10: PREÇO1 | K10: =INDEX(LISTAS!$H:$Q,MATCH(BASE!H10,LISTAS!$G:$G,0),MATCH(BASE!J10,LISTAS!$H$3:$Q$3,0))*Tabela3[[#This Row],[QUANTIDADE]] -> 12 | L10: =TEXT(Tabela3[[#This Row],[DATA]],"MM") -> 03 | M10: =WEEKNUM(Tabela3[[#This Row],[DATA]]) -> 13 | N10: =YEAR(Tabela3[[#This Row],[DATA]]) -> 2023
B11: 45013 | C11: 12035 | D11: =COUNTIF(C$4:C11,Tabela3[[#This Row],[COMANDA]]) -> 1 | E11: PRATO | F11: PIX | G11: REFEIÇÃO | H11: Bife acebolado | I11: 1 | J11: PREÇO1 | K11: =INDEX(LISTAS!$H:$Q,MATCH(BASE!H11,LISTAS!$G:$G,0),MATCH(BASE!J11,LISTAS!$H$3:$Q$3,0))*Tabela3[[#This Row],[QUANTIDADE]] -> 20 | L11: =TEXT(Tabela3[[#This Row],[DATA]],"MM") -> 03 | M11: =WEEKNUM(Tabela3[[#This Row],[DATA]]) -> 13 | N11: =YEAR(Tabela3[[#This Row],[DATA]]) -> 2023
B12: 45013 | C12: 12035 | D12: =COUNTIF(C$4:C12,Tabela3[[#This Row],[COMANDA]]) -> 2 | E12: PRATO | F12: PIX | G12: LANCHES | H12: Salgado | I12: 1 | J12: PREÇO1 | K12: =INDEX(LISTAS!$H:$Q,MATCH(BASE!H12,LISTAS!$G:$G,0),MATCH(BASE!J12,LISTAS!$H$3:$Q$3,0))*Tabela3[[#This Row],[QUANTIDADE]] -> 6 | L12: =TEXT(Tabela3[[#This Row],[DATA]],"MM") -> 03 | M12: =WEEKNUM(Tabela3[[#This Row],[DATA]]) -> 13 | N12: =YEAR(Tabela3[[#This Row],[DATA]]) -> 2023
B13: 45013 | C13: 12036 | D13: =COUNTIF(C$4:C13,Tabela3[[#This Row],[COMANDA]]) -> 1 | E13: PRATO | F13: Crédito | G13: REFEIÇÃO | H13: Bife acebolado | I13: 1 | J13: PREÇO1 | K13: =INDEX(LISTAS!$H:$Q,MATCH(BASE!H13,LISTAS!$G:$G,0),MATCH(BASE!J13,LISTAS!$H$3:$Q$3,0))*Tabela3[[#This Row],[QUANTIDADE]] -> 20 | L13: =TEXT(Tabela3[[#This Row],[DATA]],"MM") -> 03 | M13: =WEEKNUM(Tabela3[[#This Row],[DATA]]) -> 13 | N13: =YEAR(Tabela3[[#This Row],[DATA]]) -> 2023
B14: 45013 | C14: 12037 | D14: =COUNTIF(C$4:C14,Tabela3[[#This Row],[COMANDA]]) -> 1 | E14: PRATO | F14: PIX | G14: REFEIÇÃO | H14: Bife acebolado | I14: 1 | J14: Preço2 | K14: =INDEX(LISTAS!$H:$Q,MATCH(BASE!H14,LISTAS!$G:$G,0),MATCH(BASE!J14,LISTAS!$H$3:$Q$3,0))*Tabela3[[#This Row],[QUANTIDADE]] -> 18 | L14: =TEXT(Tabela3[[#This Row],[DATA]],"MM") -> 03 | M14: =WEEKNUM(Tabela3[[#This Row],[DATA]]) -> 13 | N14: =YEAR(Tabela3[[#This Row],[DATA]]) -> 2023
B15: 45013 | C15: 12038 | D15: =COUNTIF(C$4:C15,Tabela3[[#This Row],[COMANDA]]) -> 1 | E15: PRATO | F15: Débito | G15: REFEIÇÃO | H15: Linguiça | I15: 1 | J15: PREÇO1 | K15: =INDEX(LISTAS!$H:$Q,MATCH(BASE!H15,LISTAS!$G:$G,0),MATCH(BASE!J15,LISTAS!$H$3:$Q$3,0))*Tabela3[[#This Row],[QUANTIDADE]] -> 16 | L15: =TEXT(Tabela3[[#This Row],[DATA]],"MM") -> 03 | M15: =WEEKNUM(Tabela3[[#This Row],[DATA]]) -> 13 | N15: =YEAR(Tabela3[[#This Row],[DATA]]) -> 2023
... B59: 45013 | C59: 12059 | D59: =COUNTIF(C$4:C59,Tabela3[[#This Row],[COMANDA]]) -> 1 | E59: PRATO | F59: Débito | G59: REFEIÇÃO | H59: Bife acebolado | I59: 1 | J59: PREÇO1 | K59: =INDEX(LISTAS!$H:$Q,MATCH(BASE!H59,LISTAS!$G:$G,0),MATCH(BASE!J59,LISTAS!$H$3:$Q$3,0))*Tabela3[[#This Row],[QUANTIDADE]] -> 20 | L59: =TEXT(Tabela3[[#This Row],[DATA]],"MM") -> 03 | M59: =WEEKNUM(Tabela3[[#This Row],[DATA]]) -> 13 | N59: =YEAR(Tabela3[[#This Row],[DATA]]) -> 2023
B60: 45013 | C60: 12060 | D60: =COUNTIF(C$4:C60,Tabela3[[#This Row],[COMANDA]]) -> 1 | E60: PRATO | G60: REFEIÇÃO | H60: Bife acebolado | I60: 1 | J60: PREÇO1 | K60: =INDEX(LISTAS!$H:$Q,MATCH(BASE!H60,LISTAS!$G:$G,0),MATCH(BASE!J60,LISTAS!$H$3:$Q$3,0))*Tabela3[[#This Row],[QUANTIDADE]] -> 20 | L60: =TEXT(Tabela3[[#This Row],[DATA]],"MM") -> 03 | M60: =WEEKNUM(Tabela3[[#This Row],[DATA]]) -> 13 | N60: =YEAR(Tabela3[[#This Row],[DATA]]) -> 2023
B61: 45013 | C61: 12060 | D61: =COUNTIF(C$4:C61,Tabela3[[#This Row],[COMANDA]]) -> 2 | E61: PRATO | G61: BEBIDA | H61: Coca lata | I61: 1 | J61: PREÇO1 | K61: =INDEX(LISTAS!$H:$Q,MATCH(BASE!H61,LISTAS!$G:$G,0),MATCH(BASE!J61,LISTAS!$H$3:$Q$3,0))*Tabela3[[#This Row],[QUANTIDADE]] -> 4 | L61: =TEXT(Tabela3[[#This Row],[DATA]],"MM") -> 03 | M61: =WEEKNUM(Tabela3[[#This Row],[DATA]]) -> 13 | N61: =YEAR(Tabela3[[#This Row],[DATA]]) -> 2023
B62: 45013 | C62: 12061 | D62: =COUNTIF(C$4:C62,Tabela3[[#This Row],[COMANDA]]) -> 1 | E62: PRATO | F62: Crédito | G62: REFEIÇÃO | H62: Strog de frango | I62: 1 | J62: PREÇO1 | K62: =INDEX(LISTAS!$H:$Q,MATCH(BASE!H62,LISTAS!$G:$G,0),MATCH(BASE!J62,LISTAS!$H$3:$Q$3,0))*Tabela3[[#This Row],[QUANTIDADE]] -> 18 | L62: =TEXT(Tabela3[[#This Row],[DATA]],"MM") -> 03 | M62: =WEEKNUM(Tabela3[[#This Row],[DATA]]) -> 13 | N62: =YEAR(Tabela3[[#This Row],[DATA]]) -> 2023
B63: 45013 | C63: 12061 | D63: =COUNTIF(C$4:C63,Tabela3[[#This Row],[COMANDA]]) -> 2 | E63: PRATO | F63: Crédito | G63: BEBIDA | H63: Coca 600 | I63: 1 | J63: PREÇO1 | K63: =INDEX(LISTAS!$H:$Q,MATCH(BASE!H63,LISTAS!$G:$G,0),MATCH(BASE!J63,LISTAS!$H$3:$Q$3,0))*Tabela3[[#This Row],[QUANTIDADE]] -> 6 | L63: =TEXT(Tabela3[[#This Row],[DATA]],"MM") -> 03 | M63: =WEEKNUM(Tabela3[[#This Row],[DATA]]) -> 13 | N63: =YEAR(Tabela3[[#This Row],[DATA]]) -> 2023
B64: 45013 | C64: 12061 | D64: =COUNTIF(C$4:C64,Tabela3[[#This Row],[COMANDA]]) -> 3 | E64: PRATO | F64: Crédito | G64: BEBIDA | H64: Água | I64: 1 | J64: PREÇO1 | K64: =INDEX(LISTAS!$H:$Q,MATCH(BASE!H64,LISTAS!$G:$G,0),MATCH(BASE!J64,LISTAS!$H$3:$Q$3,0))*Tabela3[[#This Row],[QUANTIDADE]] -> 3 | L64: =TEXT(Tabela3[[#This Row],[DATA]],"MM") -> 03 | M64: =WEEKNUM(Tabela3[[#This Row],[DATA]]) -> 13 | N64: =YEAR(Tabela3[[#This Row],[DATA]]) -> 2023
B65: 45013 | C65: 12062 | D65: =COUNTIF(C$4:C65,Tabela3[[#This Row],[COMANDA]]) -> 1 | E65: PRATO | F65: Crédito | G65: REFEIÇÃO | H65: Do dia | I65: 1 | J65: PREÇO1 | K65: =INDEX(LISTAS!$H:$Q,MATCH(BASE!H65,LISTAS!$G:$G,0),MATCH(BASE!J65,LISTAS!$H$3:$Q$3,0))*Tabela3[[#This Row],[QUANTIDADE]] -> 16 | L65: =TEXT(Tabela3[[#This Row],[DATA]],"MM") -> 03 | M65: =WEEKNUM(Tabela3[[#This Row],[DATA]]) -> 13 | N65: =YEAR(Tabela3[[#This Row],[DATA]]) -> 2023
B66: 45013 | C66: 12062 | D66: =COUNTIF(C$4:C66,Tabela3[[#This Row],[COMANDA]]) -> 2 | E66: PRATO | F66: Crédito | G66: ADICIONAIS | H66: Linguiça Adicional | I66: 1 | J66: PREÇO1 | K66: =INDEX(LISTAS!$H:$Q,MATCH(BASE!H66,LISTAS!$G:$G,0),MATCH(BASE!J66,LISTAS!$H$3:$Q$3,0))*Tabela3[[#This Row],[QUANTIDADE]] -> 3 | L66: =TEXT(Tabela3[[#This Row],[DATA]],"MM") -> 03 | M66: =WEEKNUM(Tabela3[[#This Row],[DATA]]) -> 13 | N66: =YEAR(Tabela3[[#This Row],[DATA]]) -> 2023
B67: 45013 | C67: 12064 | D67: =COUNTIF(C$4:C67,Tabela3[[#This Row],[COMANDA]]) -> 1 | E67: PRATO | F67: Débito | G67: REFEIÇÃO | H67: Strog de frango | I67: 1 | J67: PREÇO1 | K67: =INDEX(LISTAS!$H:$Q,MATCH(BASE!H67,LISTAS!$G:$G,0),MATCH(BASE!J67,LISTAS!$H$3:$Q$3,0))*Tabela3[[#This Row],[QUANTIDADE]] -> 18 | L67: =TEXT(Tabela3[[#This Row],[DATA]],"MM") -> 03 | M67: =WEEKNUM(Tabela3[[#This Row],[DATA]]) -> 13 | N67: =YEAR(Tabela3[[#This Row],[DATA]]) -> 2023
B68: 45013 | C68: 12065 | D68: =COUNTIF(C$4:C68,Tabela3[[#This Row],[COMANDA]]) -> 1 | E68: PRATO | F68: Débito | G68: REFEIÇÃO | H68: Frango grelhado | I68: 1 | J68: PREÇO1 | K68: =INDEX(LISTAS!$H:$Q,MATCH(BASE!H68,LISTAS!$G:$G,0),MATCH(BASE!J68,LISTAS!$H$3:$Q$3,0))*Tabela3[[#This Row],[QUANTIDADE]] -> 18 | L68: =TEXT(Tabela3[[#This Row],[DATA]],"MM") -> 03 | M68: =WEEKNUM(Tabela3[[#This Row],[DATA]]) -> 13 | N68: =YEAR(Tabela3[[#This Row],[DATA]]) -> 2023
B69: 45013 | C69: 12066 | D69: =COUNTIF(C$4:C69,Tabela3[[#This Row],[COMANDA]]) -> 1 | E69: PRATO | F69: Dinheiro | G69: REFEIÇÃO | H69: Vegetariano | I69: 1 | J69: PREÇO1 | K69: =INDEX(LISTAS!$H:$Q,MATCH(BASE!H69,LISTAS!$G:$G,0),MATCH(BASE!J69,LISTAS!$H$3:$Q$3,0))*Tabela3[[#This Row],[QUANTIDADE]] -> 12 | L69: =TEXT(Tabela3[[#This Row],[DATA]],"MM") -> 03 | M69: =WEEKNUM(Tabela3[[#This Row],[DATA]]) -> 13 | N69: =YEAR(Tabela3[[#This Row],[DATA]]) -> 2023
B70: 45013 | C70: 12066 | D70: =COUNTIF(C$4:C70,Tabela3[[#This Row],[COMANDA]]) -> 2 | E70: PRATO | F70: Dinheiro | G70: BEBIDA | H70: Prats | I70: 1 | J70: PREÇO1 | K70: =INDEX(LISTAS!$H:$Q,MATCH(BASE!H70,LISTAS!$G:$G,0),MATCH(BASE!J70,LISTAS!$H$3:$Q$3,0))*Tabela3[[#This Row],[QUANTIDADE]] -> 5 | L70: =TEXT(Tabela3[[#This Row],[DATA]],"MM") -> 03 | M70: =WEEKNUM(Tabela3[[#This Row],[DATA]]) -> 13 | N70: =YEAR(Tabela3[[#This Row],[DATA]]) -> 2023
B71: 45013 | C71: 12067 | D71: =COUNTIF(C$4:C71,Tabela3[[#This Row],[COMANDA]]) -> 1 | E71: PRATO | F71: Débito | G71: REFEIÇÃO | H71: Bisteca | I71: 1 | J71: PREÇO1 | K71: =INDEX(LISTAS!$H:$Q,MATCH(BASE!H71,LISTAS!$G:$G,0),MATCH(BASE!J71,LISTAS!$H$3:$Q$3,0))*Tabela3[[#This Row],[QUANTIDADE]] -> 18 | L71: =TEXT(Tabela3[[#This Row],[DATA]],"MM") -> 03 | M71: =WEEKNUM(Tabela3[[#This Row],[DATA]]) -> 13 | N71: =YEAR(Tabela3[[#This Row],[DATA]]) -> 2023
B72: 45013 | C72: 12067 | D72: =COUNTIF(C$4:C72,Tabela3[[#This Row],[COMANDA]]) -> 2 | E72: PRATO | F72: Débito | G72: ADICIONAIS | H72: Ovo Adicional | I72: 2 | J72: PREÇO1 | K72: =INDEX(LISTAS!$H:$Q,MATCH(BASE!H72,LISTAS!$G:$G,0),MATCH(BASE!J72,LISTAS!$H$3:$Q$3,0))*Tabela3[[#This Row],[QUANTIDADE]] -> 2 | L72: =TEXT(Tabela3[[#This Row],[DATA]],"MM") -> 03 | M72: =WEEKNUM(Tabela3[[#This Row],[DATA]]) -> 13 | N72: =YEAR(Tabela3[[#This Row],[DATA]]) -> 2023
B73: 45013 | C73: 12067 | D73: =COUNTIF(C$4:C73,Tabela3[[#This Row],[COMANDA]]) -> 3 | E73: PRATO | F73: Débito | G73: BEBIDA | H73: Coca Z mine | I73: 1 | J73: PREÇO1 | K73: =INDEX(LISTAS!$H:$Q,MATCH(BASE!H73,LISTAS!$G:$G,0),MATCH(BASE!J73,LISTAS!$H$3:$Q$3,0))*Tabela3[[#This Row],[QUANTIDADE]] -> 3 | L73: =TEXT(Tabela3[[#This Row],[DATA]],"MM") -> 03 | M73: =WEEKNUM(Tabela3[[#This Row],[DATA]]) -> 13 | N73: =YEAR(Tabela3[[#This Row],[DATA]]) -> 2023
... B87: 45013 | C87: 12075 | D87: =COUNTIF(C$4:C87,Tabela3[[#This Row],[COMANDA]]) -> 2 | E87: PRATO | F87: Débito | G87: REFEIÇÃO | H87: Frango empanado | I87: 1 | J87: PREÇO1 | K87: =INDEX(LISTAS!$H:$Q,MATCH(BASE!H87,LISTAS!$G:$G,0),MATCH(BASE!J87,LISTAS!$H$3:$Q$3,0))*Tabela3[[#This Row],[QUANTIDADE]] -> 20 | L87: =TEXT(Tabela3[[#This Row],[DATA]],"MM") -> 03 | M87: =WEEKNUM(Tabela3[[#This Row],[DATA]]) -> 13 | N87: =YEAR(Tabela3[[#This Row],[DATA]]) -> 2023
B88: 45013 | C88: 12076 | D88: =COUNTIF(C$4:C88,Tabela3[[#This Row],[COMANDA]]) -> 1 | E88: PRATO | G88: REFEIÇÃO | H88: Steak | I88: 3 | J88: PREÇO1 | K88: =INDEX(LISTAS!$H:$Q,MATCH(BASE!H88,LISTAS!$G:$G,0),MATCH(BASE!J88,LISTAS!$H$3:$Q$3,0))*Tabela3[[#This Row],[QUANTIDADE]] -> 42 | L88: =TEXT(Tabela3[[#This Row],[DATA]],"MM") -> 03 | M88: =WEEKNUM(Tabela3[[#This Row],[DATA]]) -> 13 | N88: =YEAR(Tabela3[[#This Row],[DATA]]) -> 2023
B89: 45013 | C89: 12076 | D89: =COUNTIF(C$4:C89,Tabela3[[#This Row],[COMANDA]]) -> 2 | E89: PRATO | G89: REFEIÇÃO | H89: Frango empanado | I89: 1 | J89: PREÇO1 | K89: =INDEX(LISTAS!$H:$Q,MATCH(BASE!H89,LISTAS!$G:$G,0),MATCH(BASE!J89,LISTAS!$H$3:$Q$3,0))*Tabela3[[#This Row],[QUANTIDADE]] -> 20 | L89: =TEXT(Tabela3[[#This Row],[DATA]],"MM") -> 03 | M89: =WEEKNUM(Tabela3[[#This Row],[DATA]]) -> 13 | N89: =YEAR(Tabela3[[#This Row],[DATA]]) -> 2023
B90: 45013 | C90: 12077 | D90: =COUNTIF(C$4:C90,Tabela3[[#This Row],[COMANDA]]) -> 1 | E90: MARMITA | F90: Débito | G90: REFEIÇÃO | H90: Frango grelhado | I90: 1 | J90: PREÇO1 | K90: =INDEX(LISTAS!$H:$Q,MATCH(BASE!H90,LISTAS!$G:$G,0),MATCH(BASE!J90,LISTAS!$H$3:$Q$3,0))*Tabela3[[#This Row],[QUANTIDADE]] -> 18 | L90: =TEXT(Tabela3[[#This Row],[DATA]],"MM") -> 03 | M90: =WEEKNUM(Tabela3[[#This Row],[DATA]]) -> 13 | N90: =YEAR(Tabela3[[#This Row],[DATA]]) -> 2023
B91: 45013 | C91: 12077 | D91: =COUNTIF(C$4:C91,Tabela3[[#This Row],[COMANDA]]) -> 2 | E91: MARMITA | F91: Crédito | G91: REFEIÇÃO | H91: Bife acebolado | I91: 1 | J91: PREÇO1 | K91: =INDEX(LISTAS!$H:$Q,MATCH(BASE!H91,LISTAS!$G:$G,0),MATCH(BASE!J91,LISTAS!$H$3:$Q$3,0))*Tabela3[[#This Row],[QUANTIDADE]] -> 20 | L91: =TEXT(Tabela3[[#This Row],[DATA]],"MM") -> 03 | M91: =WEEKNUM(Tabela3[[#This Row],[DATA]]) -> 13 | N91: =YEAR(Tabela3[[#This Row],[DATA]]) -> 2023
B92: 45013 | C92: 12077 | D92: =COUNTIF(C$4:C92,Tabela3[[#This Row],[COMANDA]]) -> 3 | E92: MARMITA | F92: Crédito | G92: BEBIDA | H92: Coca Z lata | I92: 1 | J92: PREÇO1 | K92: =INDEX(LISTAS!$H:$Q,MATCH(BASE!H92,LISTAS!$G:$G,0),MATCH(BASE!J92,LISTAS!$H$3:$Q$3,0))*Tabela3[[#This Row],[QUANTIDADE]] -> 4 | L92: =TEXT(Tabela3[[#This Row],[DATA]],"MM") -> 03 | M92: =WEEKNUM(Tabela3[[#This Row],[DATA]]) -> 13 | N92: =YEAR(Tabela3[[#This Row],[DATA]]) -> 2023
B93: 45013 | C93: 12078 | D93: =COUNTIF(C$4:C93,Tabela3[[#This Row],[COMANDA]]) -> 1 | E93: PRATO | F93: Débito | G93: REFEIÇÃO | H93: Frango grelhado | I93: 1 | J93: PREÇO1 | K93: =INDEX(LISTAS!$H:$Q,MATCH(BASE!H93,LISTAS!$G:$G,0),MATCH(BASE!J93,LISTAS!$H$3:$Q$3,0))*Tabela3[[#This Row],[QUANTIDADE]] -> 18 | L93: =TEXT(Tabela3[[#This Row],[DATA]],"MM") -> 03 | M93: =WEEKNUM(Tabela3[[#This Row],[DATA]]) -> 13 | N93: =YEAR(Tabela3[[#This Row],[DATA]]) -> 2023
B94: 45013 | C94: 12079 | D94: =COUNTIF(C$4:C94,Tabela3[[#This Row],[COMANDA]]) -> 1 | E94: PRATO | F94: Crédito | G94: REFEIÇÃO | H94: Linguiça | I94: 1 | J94: PREÇO1 | K94: =INDEX(LISTAS!$H:$Q,MATCH(BASE!H94,LISTAS!$G:$G,0),MATCH(BASE!J94,LISTAS!$H$3:$Q$3,0))*Tabela3[[#This Row],[QUANTIDADE]] -> 16 | L94: =TEXT(Tabela3[[#This Row],[DATA]],"MM") -> 03 | M94: =WEEKNUM(Tabela3[[#This Row],[DATA]]) -> 13 | N94: =YEAR(Tabela3[[#This Row],[DATA]]) -> 2023
B95: 45013 | C95: 12079 | D95: =COUNTIF(C$4:C95,Tabela3[[#This Row],[COMANDA]]) -> 2 | E95: PRATO | F95: Crédito | G95: REFEIÇÃO | H95: Frango grelhado | I95: 1 | J95: PREÇO1 | K95: =INDEX(LISTAS!$H:$Q,MATCH(BASE!H95,LISTAS!$G:$G,0),MATCH(BASE!J95,LISTAS!$H$3:$Q$3,0))*Tabela3[[#This Row],[QUANTIDADE]] -> 18 | L95: =TEXT(Tabela3[[#This Row],[DATA]],"MM") -> 03 | M95: =WEEKNUM(Tabela3[[#This Row],[DATA]]) -> 13 | N95: =YEAR(Tabela3[[#This Row],[DATA]]) -> 2023
B96: 45013 | C96: 12080 | D96: =COUNTIF(C$4:C96,Tabela3[[#This Row],[COMANDA]]) -> 1 | E96: PRATO | G96: REFEIÇÃO | H96: Vegetariano | I96: 1 | J96: PREÇO1 | K96: =INDEX(LISTAS!$H:$Q,MATCH(BASE!H96,LISTAS!$G:$G,0),MATCH(BASE!J96,LISTAS!$H$3:$Q$3,0))*Tabela3[[#This Row],[QUANTIDADE]] -> 12 | L96: =TEXT(Tabela3[[#This Row],[DATA]],"MM") -> 03 | M96: =WEEKNUM(Tabela3[[#This Row],[DATA]]) -> 13 | N96: =YEAR(Tabela3[[#This Row],[DATA]]) -> 2023
B97: 45013 | C97: 12081 | D97: =COUNTIF(C$4:C97,Tabela3[[#This Row],[COMANDA]]) -> 1 | E97: PRATO | F97: Débito | G97: REFEIÇÃO | H97: Frango grelhado | I97: 1 | J97: PREÇO1 | K97: =INDEX(LISTAS!$H:$Q,MATCH(BASE!H97,LISTAS!$G:$G,0),MATCH(BASE!J97,LISTAS!$H$3:$Q$3,0))*Tabela3[[#This Row],[QUANTIDADE]] -> 18 | L97: =TEXT(Tabela3[[#This Row],[DATA]],"MM") -> 03 | M97: =WEEKNUM(Tabela3[[#This Row],[DATA]]) -> 13 | N97: =YEAR(Tabela3[[#This Row],[DATA]]) -> 2023
B98: 45013 | C98: 12081 | D98: =COUNTIF(C$4:C98,Tabela3[[#This Row],[COMANDA]]) -> 2 | E98: PRATO | F98: Débito | G98: REFEIÇÃO | H98: Strog de frango | I98: 1 | J98: PREÇO1 | K98: =INDEX(LISTAS!$H:$Q,MATCH(BASE!H98,LISTAS!$G:$G,0),MATCH(BASE!J98,LISTAS!$H$3:$Q$3,0))*Tabela3[[#This Row],[QUANTIDADE]] -> 18 | L98: =TEXT(Tabela3[[#This Row],[DATA]],"MM") -> 03 | M98: =WEEKNUM(Tabela3[[#This Row],[DATA]]) -> 13 | N98: =YEAR(Tabela3[[#This Row],[DATA]]) -> 2023
...

Sheet LISTAS
B3: FORMAS DE ENTREGA | D3: FORMA DE PAGAMENTO | F3: CATEGORIA | G3: ITEM | H3: PREÇO1 | I3: PREÇO2 | J3: PREÇO3 | K3: PREÇO4 | L3: PREÇO5
B4: MARMITA | D4: PIX | F4: BEBIDA | G4: Coca lata | H4: 4 | I4: 4.5 | J4: 5
B5: PRATO | D5: CARTÃO DE DÉBITO | F5: BEBIDA | G5: Coca mine | H5: 3 | I5: 3.5 | J5: 4
B6: ENTREGA | D6: CARTÃO DE CRÉDITO | F6: BEBIDA | G6: Coca Z lata | H6: 4 | I6: 4.5 | J6: 5
B7: BALCÃO | D7: DINHEIRO | F7: BEBIDA | G7: Coca Z mine | H7: 3 | I7: 3.5 | J7: 4
F8: BEBIDA | G8: Coca 600 | H8: 6 | I8: 7
F9: BEBIDA | G9: Coca Z 600 | H9: 6 | I9: 7
F10: BEBIDA | G10: Sprite lata | H10: 4 | I10: 4.5 | J10: 5
F11: BEBIDA | G11: Sprite mine | H11: 3 | I11: 3.5 | J11: 4
F12: BEBIDA | G12: Schweppes lata | H12: 4.5 | I12: 5 | J12: 5.5
F13: BEBIDA | G13: Schweppes mine | H13: 3.5 | I13: 4
F14: BEBIDA | G14: Guaraná lata | H14: 4 | I14: 4.5 | J14: 5
F15: BEBIDA | G15: Guaraná 600 | H15: 6 | I15: 7
F16: BEBIDA | G16: Fanta Laranja 500 | H16: 6 | I16: 7
F17: BEBIDA | G17: Fanta Uva 500 | H17: 6 | I17: 7
F18: BEBIDA | G18: Fanta Uva lata | H18: 4 | I18: 4.5 | J18: 5
F19: BEBIDA | G19: Fanta Laranja lata | H19: 4 | I19: 4.5 | J19: 5
F20: BEBIDA | G20: Fanta Uva mine | H20: 3 | I20: 3.5 | J20: 4
F21: BEBIDA | G21: Fanta Laranja mine | H21: 3 | I21: 3.5 | J21: 4
F22: BEBIDA | G22: Guaraviton | H22: 6
F23: BEBIDA | G23: Coca 1,5L | H23: 8
F24: BEBIDA | G24: Coca 2L | H24: 10 | I24: 12
F25: BEBIDA | G25: Guaraná 1,5 | H25: 8 | I25: 10
F26: BEBIDA | G26: Guaraná 1L | H26: 7
F27: BEBIDA | G27: Caçulinha | H27: 3
F28: BEBIDA | G28: Água | H28: 3
F29: BEBIDA | G29: Água com gás | H29: 3
F30: BEBIDA | G30: Ice Tea | H30: 5
F31: BEBIDA | G31: Prats | H31: 5
F32: BEBIDA | G32: Caixinha | H32: 3
F33: BEBIDA | G33: H2O | H33: 6 | I33: 7
F34: BEBIDA | G34: Monster | H34: 10 | I34: 12
F35: BEBIDA | G35: Red Bull | H35: 10
F36: BEBIDA | G36: Suco 500 | H36: 6
F37: BEBIDA | G37: Achocolatado | H37: 3
F38: BEBIDA | G38: Café Simples | H38: 1
F39: BEBIDA | G39: Café Duplo | H39: 2
F40: BEBIDA | G40: Pingado 100 | H40: 1.5
F41: BEBIDA | G41: Pingado 200 | H41: 3
F42: BEBIDA | G42: Pingado 300 | H42: 4
...

Sheet TABELAS
A4: FILTRO | C4: Valores
A5: MÊS | C5: FATURAMENTO | D5: 191021.1
A6: SEMANA | C6: PEDIDOS | D6: 6510
A7: DIA | C7: ITENS | D7: 13628
A8: FORMA DE ENTREGA
A10: FATURAMENTO | C10: FATURAMENTO | P10: PEDIDOS | AC10: ITENS
A11: CARD
A12: POR SEMANA | C12: SEMANA | D12: FATURAMENTO | F12: ENTREGA | G12: FATURAMENTO | I12: PAGAMENTOS | J12: FATURAMENTO | L12: ITEM | M12: FATURAMENTO | P12: SEMANA | Q12: PEDIDOS | S12: ENTREGA | T12: PEDIDOS | V12: PAGAMENTO | W12: PEDIDOS | Y12: ITEM | Z12: PEDIDOS | AC12: SEMANA | AD12: ITENS | AF12: ENTREGA | AG12: ITENS | AI12: PAGAMENTO | AJ12: ITENS | AL12: ITEM | AM12: ITENS
A13: POR FORMA DE ENTREGA | C13: 03 | D13: 8768.2 | F13: (vazio) | G13: 16 | I13: (vazio) | J13: 42315.85 | L13: REFEIÇÃO | M13: 145294.5 | P13: 03 | S13: (vazio) | T13: 1 | V13: (vazio) | W13: 2913 | Y13: MISTO | Z13: 161 | AC13: 03 | AD13: 939 | AF13: (vazio) | AG13: 2 | AI13: (vazio) | AJ13: 7243 | AL13: MISTO | AM13: 750
A14: POR FORMA DE PAGAMENTO | C14: 04 | D14: 44466.35 | F14: BALCÃO | G14: 27921.15 | I14: Crédito | J14: 54216.55 | L14: MISTO | M14: 3898.5 | P14: 13 | Q14: 636 | S14: BALCÃO | T14: 1955 | V14: Crédito | W14: 3990 | Y14: ADICIONAIS | Z14: 844 | AC14: 04 | AD14: 5013 | AF14: BALCÃO | AG14: 6181 | AI14: Crédito | AJ14: 4375 | AL14: ADICIONAIS | AM14: 977
A15: POR CATEGORIA E ITEM | C15: 05 | D15: 48303.2 | F15: MARMITA | G15: 24718.7 | I15: Débito | J15: 59788.2 | L15: ADICIONAIS | M15: 2816 | P15: 04 | S15: MARMITA | T15: 1586 | V15: Débito | W15: 4311 | Y15: BEBIDA | Z15: 3588 | AC15: 05 | AD15: 5608 | AF15: MARMITA | AG15: 1778 | AI15: Débito | AJ15: 4812 | AL15: BEBIDA | AM15: 5008
C16: 06 | D16: 33228.5 | F16: PRATO | G16: 138365.25 | I16: Dinheiro | J16: 16209.5 | L16: BEBIDA | M16: 20691.9 | P16: 14 | Q16: 800 | S16: PRATO | T16: 10086 | V16: Dinheiro | W16: 1178 | Y16: CUSCUZ | Z16: 62 | AC16: 06 | AD16: 3062 | AF16: PRATO | AG16: 11075 | AI16: Dinheiro | AJ16: 1262 | AL16: CUSCUZ | AM16: 69
A17: PEDIDOS | C17: 07 | D17: 34895.45 | F17: Total Geral | G17: 191021.1 | I17: PIX | J17: 18491 | L17: CUSCUZ | M17: 634 | P17: 15 | Q17: 901 | S17: Total Geral | T17: 13628 | V17: PIX | W17: 1236 | Y17: LANCHES | Z17: 178 | AC17: 07 | AD17: 2739 | AF17: Total Geral | AG17: 19036 | AI17: PIX | AJ17: 1344 | AL17: LANCHES | AM17: 1322
A18: CARD | C18: 08 | D18: 21359.4 | I18: Total Geral | J18: 191021.1 | L18: LANCHES | M18: 5869.9 | P18: 16 | Q18: 690 | V18: Total Geral | W18: 13628 | Y18: PORÇÕES | Z18: 151 | AC18: 08 | AI18: Total Geral | AJ18: 19036 | AL18: PORÇÕES | AM18: 243
A19: POR SEMANA | C19: Total Geral | D19: 191021.1 | L19: PORÇÕES | M19: 1060 | P19: 17 | Q19: 776 | Y19: REFEIÇÃO | Z19: 7616 | AC19: 31 | AD19: 347 | AL19: REFEIÇÃO | AM19: 8400
A20: POR FORMA DE ENTREGA | L20: SOBREMESA | M20: 8717.8 | P20: 05 | Y20: SOBREMESA | Z20: 842 | AC20: 32 | AD20: 307 | AL20: SOBREMESA | AM20: 2025
A21: POR FORMA DE PAGAMENTO | L21: TAPIOCA | M21: 2038.5 | P21: 18 | Q21: 868 | Y21: TAPIOCA | Z21: 186 | AC21: 33 | AD21: 580 | AL21: TAPIOCA | AM21: 242
A22: POR CATEGORIA E ITEM | L22: Total Geral | M22: 191021.1 | P22: 19 | Q22: 827 | Y22: Total Geral | Z22: 13628 | AC22: 34 | AD22: 441 | AL22: Total Geral | AM22: 19036
P23: 20 | Q23: 717 | AC23: Total Geral | AD23: 19036
A24: ITENS | P24: 21 | Q24: 766
A25: CARD | P25: 22 | Q25: 379
A26: POR SEMANA | P26: 06
A27: POR FORMA DE ENTREGA | P27: 22 | Q27: 506
A28: POR FORMA DE PAGAMENTO | P28: 23 | Q28: 367
A29: POR CATEGORIA E ITEM | P29: 24 | Q29: 452
P30: 25 | Q30: 505
P31: 26 | Q31: 516
P32: 07
P33: 27 | Q33: 576
P34: 28 | Q34: 727
P35: 29 | Q35: 468
P36: 30 | Q36: 608
P37: 31 | Q37: 76
P38: 08
P39: 31 | Q39: 297
P40: 32 | Q40: 279
P41: 33 | Q41: 503
P42: 34 | Q42: 388
P43: Total Geral | Q43: 13628

Sheet PAINEL

Sheet Compras
B1: Compras 28/03/2023 a 01/04/2023 | J1: Compras 02/04/2023 a 08/04/2023 | R1: Compras 09/04/2023 a 15/04/2023 | Z1: Compras 16/04/2023 a 22/04/2023 | AH1: Compras 23/04/2023 a 29/04/2023 | AP1: Compras 30/04/2023 a 06/05/2023 | AX1: Compras 07/05/2023 a 13/05/2023 | BF1: Compras 14/05/2023 a 20/05/2023 | BN1: Compras 21/05/2023 a 27/05/2023 | BV1: Compras 28/05/2023 a 03/06/2023 | CD1: Compras 04/06/2023 a 10/06/2023 | CL1: Compras 11/06/2023 a 17/06/2023 | CT1: Compras 18/06/2023 a 24/06/2023 | DB1: Compras 25/06/2023 a 01/07/2023 | DJ1: Compras 02/07/2023 a 08/07/2023 | DR1: Compras 09/07/2023 a 15/07/2023 | DZ1: Compras 16/07/2023 a 22/07/2023 | EH1: Compras 23/07/2023 a 29/07/2023 | EP1: Compras 30/07/2023 a 05/08/2023 | EX1: Compras 06/08/2023 a 12/08/2023 | FF1: Compras 13/08/2023 a 19/08/2023 | FN1: Compras 20/08/2023 a 26/08/2023
B3: 45014 | C3: ITEM | D3: MARCA | E3: QNT. | F3: R$ UND. | G3: DESC. | H3: TOTAL | J3: 45018 | K3: ITEM | L3: MARCA | M3: QNT. | N3: R$ UND. | O3: DESC. | P3: TOTAL | AP3: 45048 | AQ3: ITEM | AR3: MARCA | AS3: QNT. | AT3: R$ UND. | AU3: DESC. | AV3: TOTAL | AX3: 45053 | AY3: ITEM | AZ3: MARCA | BA3: QNT. | BB3: R$ UND. | BC3: DESC. | BD3: TOTAL | BF3: 45061 | BG3: ITEM | BH3: MARCA | BI3: QNT. | BJ3: R$ UND. | BK3: DESC. | BL3: TOTAL | BN3: 45069 | BO3: ITEM | BP3: MARCA | BQ3: QNT. | BR3: R$ UND. | BS3: DESC. | BT3: TOTAL | BV3: 45075 | BW3: ITEM | BX3: MARCA | BY3: QNT. | BZ3: R$ UND. | CA3: DESC. | CB3: TOTAL | CD3: 45082 | CE3: ITEM | CF3: MARCA | CG3: QNT. | CH3: R$ UND. | CI3: DESC. | CJ3: TOTAL | CL3: 45090 | CM3: ITEM | CN3: MARCA | CO3: QNT. | CP3: R$ UND. | CQ3: DESC. | CR3: TOTAL | CT3: 45096 | CU3: ITEM | CV3: MARCA | CW3: QNT. | CX3: R$ UND. | CY3: DESC. | CZ3: TOTAL | DB3: 45103 | DC3: ITEM | DD3: MARCA | DE3: QNT. | DF3: R$ UND. | DG3: DESC. | DH3: TOTAL | DZ3: 45125 | EA3: ITEM | EB3: MARCA | EC3: QNT. | ED3: R$ UND. | EE3: DESC. | EF3: TOTAL | EH3: 45131 | EI3: ITEM | EJ3: MARCA | EK3: QNT. | EL3: R$ UND. | EM3: DESC. | EN3: TOTAL
B4: Big Box | C4: Coxão mole | E4: 30.034 | F4: 29.9 | H4: =(E4*F4)-G4 -> 898.0166 | J4: Atacadão | K4: Sacola | M4: 3 | N4: 0.24 | P4: =(M4*N4)-O4 -> 0.72 | R4: 45027 | S4: ITEM | T4: MARCA | U4: QNT. | V4: R$ UND. | W4: DESC. | X4: TOTAL | AP4: Atacadão | AQ4: Batata palha | AS4: 3 | AT4: 17.9 | AV4: =(AS4*AT4)-AU4 -> 53.7 | AX4: Assai | AY4: Pão | BA4: 0.204 | BB4: 12.9 | BD4: =(BA4*BB4)-BC4 -> 2.6316 | BF4: Adf comercial | BG4: Cebola | BI4: 1 | BJ4: 70 | BL4: =(BI4*BJ4)-BK4 -> 70 | BN4: LG distribuidora | BO4: Molho pimenta | BQ4: 1 | BR4: 12.6 | BT4: =(BQ4*BR4)-BS4 -> 12.6 | BV4: Natural Brasil | BW4: Barra açai | BY4: 10 | BZ4: 14.6 | CB4: =(BY4*BZ4)-CA4 -> 146 | CD4: Assai | CE4: LL Poly | CG4: 6 | CH4: 1.55 | CI4: 0.6 | CJ4: =(CG4*CH4)-CI4 -> 8.7 | CL4: estaçaõ dos frios | CM4: Mussarela | CO4: 3.952 | CP4: 36.9 | CR4: =(CO4*CP4)-CQ4 -> 145.8288 | CT4: Mega fox Distr. | CU4: Mentos | CW4: 4 | CX4: 23.5325 | CZ4: =CW4*CX4-CY4 -> 94.13 | DB4: D' Ouro minas | DC4: Salgado Comum | DE4: 30 | DF4: 3 | DH4: =(DE4*DF4)-DG4 -> 90 | DJ4: 45110 | DK4: ITEM | DL4: MARCA | DM4: QNT. | DN4: R$ UND. | DO4: DESC. | DP4: TOTAL | DR4: 45117 | DS4: ITEM | DT4: MARCA | DU4: QNT. | DV4: R$ UND. | DW4: DESC. | DX4: TOTAL | DZ4: Atacadão | EA4: Extrato | EC4: 1 | ED4: 23.9 | EF4: =EC4*ED4-EE4 -> 23.9 | EH4: Finos salgados | EI4: Salgados | EK4: 40 | EL4: 2.75 | EN4: =(EK4*EL4)-EM4 -> 110 | EP4: 45138 | EQ4: ITEM | ER4: MARCA | ES4: QNT. | ET4: R$ UND. | EU4: DESC. | EV4: TOTAL | EX4: 45145 | EY4: ITEM | EZ4: MARCA | FA4: QNT. | FB4: R$ UND. | FC4: DESC. | FD4: TOTAL | FF4: 45152 | FG4: ITEM | FH4: MARCA | FI4: QNT. | FJ4: R$ UND. | FK4: DESC. | FL4: TOTAL | FN4: 45159 | FO4: ITEM | FP4: MARCA | FQ4: QNT. | FR4: R$ UND. | FS4: DESC. | FT4: TOTAL
C5: Coca mine | E5: 18 | F5: 1.89 | H5: =(E5*F5)-G5 -> 34.02 | K5: Coca 600 | M5: 15 | N5: 3.49 | P5: =(M5*N5)-O5 -> 52.35 | R5: Sobradinho carnes | S5: Musculo | U5: 5.146 | V5: 24.99 | X5: =(U5*V5)-W5 -> 128.59854 | AH5: 45041 | AI5: ITEM | AJ5: MARCA | AK5: QNT. | AL5: R$ UND. | AM5: DESC. | AN5: TOTAL | AQ5: Sal | AS5: 3 | AT5: 1.99 | AV5: =(AS5*AT5)-AU5 -> 5.97 | AY5: Requeijão | BA5: 1 | BB5: 14.49 | BD5: =(BA5*BB5)-BC5 -> 14.49 | BF5: Crédito | BG5: TOTAL | BL5: =SUM(BL4:BL4) -> 70 | BO5: Molho pimenta | BQ5: 2 | BR5: 6.49 | BT5: =(BQ5*BR5)-BS5 -> 12.98 | BW5: Barra acerola | BY5: 5 | BZ5: 11.5 | CB5: =(BY5*BZ5)-CA5 -> 57.5 | CE5: Arisco | CG5: 3 | CH5: 4.99 | CI5: 1.5 | CJ5: =(CG5*CH5)-CI5 -> 13.47 | CM5: Presunto | CO5: 2.95 | CP5: 23.5 | CR5: =(CO5*CP5)-CQ5 -> 69.325 | CU5: Chiclete POOSH | CW5: 12 | CX5: 5.1833 | CZ5: =CW5*CX5-CY5 -> 62.1996 | DB5: Dinheiro | DC5: TOTAL | DH5: =SUM(DH4:DH4) -> 90 | DJ5: Sobradinho Carnes | DK5: Coxaõ mole | DM5: 31.27 | DN5: 27.99 | DP5: =(DM5*DN5)-DO5 -> 875.2473 | DR5: D' Ouro minas | DS5: Salgado Comum | DU5: 30 | DV5: 3 | DX5: =(DU5*DV5)-DW5 -> 90 | EA5: Caldo | EC5: 1 | ED5: 10.9 | EF5: =EC5*ED5-EE5 -> 10.9 | EH5: Dinheiro | EI5: TOTAL | EN5: =SUM(EN4:EN4) -> 110 | EP5: Levo | EQ5: Batata | ES5: 24 | ET5: 10.99 | EV5: =(ES5*ET5)-EU5 -> 263.76 | EX5: Natural Brasil | EY5: Barra Açai | FA5: 3 | FB5: 15.2 | FD5: =(FA5*FB5)-FC5 -> 45.6 | FF5: Levo | FG5: Batata | FI5: 12 | FJ5: 11.4 | FL5: =(FI5*FJ5)-FK5 -> 136.8 | FN5: Atacadão | FO5: Farinha | FQ5: 10 | FR5: 5.69 | FS5: 2 | FT5: =(FQ5*FR5)-FS5 -> 54.9
C6: Queijo cotagge | E6: 1 | F6: 13.99 | H6: =(E6*F6)-G6 -> 13.99 | K6: Coca Z 600 | M6: 12 | N6: 3.49 | P6: =(M6*N6)-O6 -> 41.88 | S6: Acem | U6: 6.12 | V6: 19.99 | X6: =(U6*V6)-W6 -> 122.3388 | AH6: Ovo | AI6: Ovo | AK6: 1 | AL6: 288.88 | AM6: 53.88 | AN6: =(AK6*AL6)-AM6 -> 235 | AQ6: Catchupe sache | AS6: 1 | AT6: 11.89 | AV6: =(AS6*AT6)-AU6 -> 11.89 | AY6: Schweppes lata | BA6: 6 | BB6: 2.79 | BC6: 0.6 | BD6: =(BA6*BB6)-BC6 -> 16.14 | BO6: Refresco guaramix | BQ6: 2 | BR6: 36.13 | BT6: =(BQ6*BR6)-BS6 -> 72.26 | BW6: Amendoim farofa | BY6: 1 | BZ6: 16.5 | CB6: =(BY6*BZ6)-CA6 -> 16.5 | CE6: Barakell | CG6: 1 | CH6: 9.95 | CJ6: =(CG6*CH6)-CI6 -> 9.95 | CL6: Crédito | CM6: TOTAL | CR6: =SUM(CR4:CR5) -> 215.1538 | CU6: Pirulito BIGBIG | CW6: 2 | CX6: 10.2833 | CZ6: =CW6*CX6-CY6 -> 20.5666 | DK6: Musculo | DM6: 4.758 | DN6: 22.99 | DP6: =(DM6*DN6)-DO6 -> 109.38642 | DR6: Dinheiro | DS6: TOTAL | DX6: =SUM(DX5:DX5) -> 90 | EA6: Saco lixo | EC6: 1 | ED6: 28.9 | EF6: =EC6*ED6-EE6 -> 28.9 | EP6: ? | EQ6: TOTAL | EV6: =SUM(EV5:EV5) -> 263.76 | EY6: Bananada | FA6: 1 | FB6: 9.6 | FD6: =(FA6*FB6)-FC6 -> 9.6 | FF6: ? | FG6: TOTAL | FL6: =SUM(FL5:FL5) -> 136.8 | FO6: Batata frita | FQ6: 10 | FR6: 19.9 | FT6: =(FQ6*FR6)-FS6 -> 199
C7: Mussarela | E7: 0.514 | F7: 39.9 | H7: =(E7*F7)-G7 -> 20.5086 | K7: Red Bull | M7: 1 | N7: 29.16 | P7: =(M7*N7)-O7 -> 29.16 | R7: Crédito | S7: TOTAL | X7: =SUM(X5:X6) -> 250.93734 | Z7: 45033 | AA7: ITEM | AB7: MARCA | AC7: QNT. | AD7: R$ UND. | AE7: DESC. | AF7: TOTAL | AH7: ? | AI7: TOTAL | AN7: =SUM(AN6:AN6) -> 235 | AQ7: Maionese sache | AS7: 1 | AT7: 11.69 | AV7: =(AS7*AT7)-AU7 -> 11.69 | AY7: Sprite lata | BA7: 18 | BB7: 1.85 | BC7: 1.8 | BD7: =(BA7*BB7)-BC7 -> 31.5 | BF7: 45061 | BG7: ITEM | BH7: MARCA | BI7: QNT. | BJ7: R$ UND. | BK7: DESC. | BL7: TOTAL | BO7: Amendupã bacon | BQ7: 1 | BR7: 21.98 | BT7: =(BQ7*BR7)-BS7 -> 21.98 | BV7: ? | BW7: TOTAL | CB7: =SUM(CB4:CB6) -> 220 | CE7: Café | CG7: 2 | CH7: 13.79 | CJ7: =(CG7*CH7)-CI7 -> 27.58 | CU7: Pirulito BIGBIG | CW7: 2 | CX7: 10.6218 | CZ7: =CW7*CX7-CY7 -> 21.2436 | DB7: 45103 | DC7: ITEM | DD7: MARCA | DE7: QNT. | DF7: R$ UND. | DG7: DESC. | DH7: TOTAL | DK7: Miolo de acem | DM7: 4.92 | DN7: 22.99 | DP7: =(DM7*DN7)-DO7 -> 113.1108 | EA7: Jogo faca | EC7: 1 | ED7: 41.9 | EF7: =EC7*ED7-EE7 -> 41.9 | EH7: 45131 | EI7: ITEM | EJ7: MARCA | EK7: QNT. | EL7: R$ UND. | EM7: DESC. | EN7: TOTAL | EX7: ? | EY7: TOTAL | FD7: =SUM(FD5:FD6) -> 55.2 | FN7: Crédito | FO7: TOTAL | FT7: =SUM(FT5:FT6) -> 253.9
C8: Presunto | E8: 0.364 | F8: 28.9 | H8: =(E8*F8)-G8 -> 10.5196 | K8: Monster | M8: 40 | N8: 6.79 | P8: =(M8*N8)-O8 -> 271.6 | Z8: Finos salgados | AA8: Salgados | AC8: 65 | AD8: 2.75 | AF8: =(AC8*AD8)-AE8 -> 178.75 | AQ8: Coca cola | AS8: 1 | AT8: 25.08 | AV8: =(AS8*AT8)-AU8 -> 25.08 | AY8: Coca mine | BA8: 24 | BB8: 1.89 | BC8: 2.4 | BD8: =(BA8*BB8)-BC8 -> 42.96 | BF8: Atacadão | BG8: Pão de forma | BI8: 3 | BJ8: 5.49 | BL8: =(BI8*BJ8)-BK8 -> 16.47 | BO8: Amendupã Calabresa | BQ8: 1 | BR8: 21.98 | BT8: =(BQ8*BR8)-BS8 -> 21.98 | CE8: Saleiro | CG8: 1 | CH8: 1.39 | CJ8: =(CG8*CH8)-CI8 -> 1.39 | CL8: 45090 | CM8: ITEM | CN8: MARCA | CO8: QNT. | CP8: R$ UND. | CQ8: DESC. | CR8: TOTAL | CU8: 7Belo | CW8: 2 | CX8: 9.7999 | CZ8: =CW8*CX8-CY8 -> 19.5998 | DB8: Finos salgados | DC8: Salgados | DE8: 65 | DF8: 2.75 | DH8: =(DE8*DF8)-DG8 -> 178.75 | DK8: Figado | DM8: 3.585 | DN8: 9.99 | DP8: =(DM8*DN8)-DO8 -> 35.81415 | DR8: 45117 | DS8: ITEM | DT8: MARCA | DU8: QNT. | DV8: R$ UND. | DW8: DESC. | DX8: TOTAL | EA8: Tomate | EC8: 4.565 | ED8: 8.99 | EF8: =EC8*ED8-EE8 -> 41.03935 | EH8: CEASA | EI8: Chuchu | EK8: 1 | EL8: 20 | EN8: =EK8*EL8-EM8 -> 20 | EP8: 45139 | EQ8: ITEM | ER8: MARCA | ES8: QNT. | ET8: R$ UND. | EU8: DESC. | EV8: TOTAL | FF8: 45153 | FG8: ITEM | FH8: MARCA | FI8: QNT. | FJ8: R$ UND. | FK8: DESC. | FL8: TOTAL
C9: Pão frances | E9: 0.165 | F9: 18.99 | H9: =(E9*F9)-G9 -> 3.13335 | K9: Arroz | M9: 1 | N9: 7.29 | P9: =(M9*N9)-O9 -> 7.29 | R9: 45027 | S9: ITEM | T9: MARCA | U9: QNT. | V9: R$ UND. | W9: DESC. | X9: TOTAL | Z9: ? | AA9: TOTAL | AF9: =SUM(AF8:AF8) -> 178.75 | AH9: 45041 | AI9: ITEM | AJ9: MARCA | AK9: QNT. | AL9: R$ UND. | AM9: DESC. | AN9: TOTAL | AQ9: Acucar | AS9: 1 | AT9: 17.99 | AV9: =(AS9*AT9)-AU9 -> 17.99 | AY9: Coca 600 | BA9: 90 | BB9: 1.99 | BD9: =(BA9*BB9)-BC9 -> 179.1 | BG9: Polvilho | BI9: 2 | BJ9: 8.39 | BL9: =(BI9*BJ9)-BK9 -> 16.78 | BO9: Amendupã Churrasco | BQ9: 1 | BR9: 21.98 | BT9: =(BQ9*BR9)-BS9 -> 21.98 | BV9: 45076 | BW9: ITEM | BX9: MARCA | BY9: QNT. | BZ9: R$ UND. | CA9: DESC. | CB9: TOTAL | CE9: Catchup | CG9: 2 | CH9: 17.9 | CJ9: =(CG9*CH9)-CI9 -> 35.8 | CL9: Fortes Embalagens | CM9: Toalha americana | CO9: 2 | CP9: 25.9 | CQ9: 5.18 | CR9: =(CO9*CP9)-CQ9 -> 46.62 | CT9: ? | CU9: TOTAL | CZ9: =SUM(CZ4:CZ8) -> 217.7396 | DB9: Dinheiro | DC9: TOTAL | DH9: =SUM(DH8:DH8) -> 178.75 | DK9: Capa de contrafile | DM9: 1.978 | DN9: 22.99 | DP9: =(DM9*DN9)-DO9 -> 45.47422 | DR9: Finos salgados | DS9: Salgados | DU9: 65 | DV9: 2.75 | DX9: =(DU9*DV9)-DW9 -> 178.75 | EA9: tempero arisco | EC9: 5 | ED9: 4.99 | EF9: =EC9*ED9-EE9 -> 24.95 | EI9: Tomate | EK9: 1 | EL9: 50 | EN9: =EK9*EL9-EM9 -> 50 | EP9: Finos salgados | EQ9: Salgados | ES9: 40 | ET9: 2.75 | EV9: =(ES9*ET9)-EU9 -> 110 | EX9: 45145 | EY9: ITEM | EZ9: MARCA | FA9: QNT. | FB9: R$ UND. | FC9: DESC. | FD9: TOTAL | FF9: Friatto | FG9: Linguiça de frango | FI9: 20 | FJ9: 15.49 | FL9: =(FI9*FJ9)-FK9 -> 309.8
C10: Sucrilhos | E10: 1 | F10: 6.99 | H10: =(E10*F10)-G10 -> 6.99 | K10: Red Bull | M10: 6 | N10: 7.29 | P10: =(M10*N10)-O10 -> 43.74 | R10: Finos salgados | S10: Salgados | U10: 75 | V10: 2.75 | X10: =(U10*V10)-W10 -> 206.25 | AH10: Finos salgados | AI10: Salgados | AK10: 80 | AL10: 2.75 | AN10: =(AK10*AL10)-AM10 -> 220 | AQ10: Coca 600 | AS10: 15 | AT10: 3.69 | AV10: =(AS10*AT10)-AU10 -> 55.35 | AY10: Ovo | BA10: 1 | BB10: 239 | BD10: =(BA10*BB10)-BC10 -> 239 | BG10: Flocão | BI10: 3 | BJ10: 1.89 | BL10: =(BI10*BJ10)-BK10 -> 5.67 | BN10: ? | BO10: TOTAL | BT10: =SUM(BT4:BT9) -> 163.78 | BV10: Sobradinho Carnes | BW10: Figado | BY10: 3.858 | BZ10: 14.99 | CB10: =(BY10*BZ10)-CA10 -> 57.83142 | CE10: Maionese | CG10: 1 | CH10: 22.9 | CJ10: =(CG10*CH10)-CI10 -> 22.9 | CM10: Sco hamburguer | CO10: 2 | CP10: 5.9 | CQ10: 1.18 | CR10: =(CO10*CP10)-CQ10 -> 10.62 | DJ10: Crédito | DK10: TOTAL | DP10: =SUM(DP5:DP9) -> 1179.0329 | DR10: Dinheiro | DS10: TOTAL | DX10: =SUM(DX9:DX9) -> 178.75 | EA10: Coca lata | EC10: 1 | ED10: 13.74 | EF10: =EC10*ED10-EE10 -> 13.74 | EI10: Cenoura | EK10: 1 | EL10: 50 | EN10: =EK10*EL10-EM10 -> 50 | EP10: Dinheiro | EQ10: TOTAL | EV10: =SUM(EV9:EV9) -> 110 | EX10: Estação dos frios | EY10: Presunto | FA10: 2.054 | FB10: 23.5 | FD10: =(FA10*FB10)-FC10 -> 48.269 | FF10: ? | FG10: TOTAL | FL10: =SUM(FL9:FL9) -> 309.8
B11: Crédito | C11: TOTAL | H11: =SUM(H4:H10,) -> 987.17815 | J11: Crédito | K11: TOTAL | P11: =SUM(P4:P10,) -> 446.74 | R11: ? | S11: TOTAL | X11: =SUM(X10:X10) -> 206.25 | Z11: 45033 | AA11: ITEM | AB11: MARCA | AC11: QNT. | AD11: R$ UND. | AE11: DESC. | AF11: TOTAL | AH11: ? | AI11: TOTAL | AN11: =SUM(AN10:AN10) -> 220 | AQ11: Agua | AS11: 24 | AT11: 1.19 | AV11: =(AS11*AT11)-AU11 -> 28.56 | AX11: Crédito | AY11: TOTAL | BD11: =SUM(BD4:BD10) -> 525.8216 | BG11: Sabao em po | BI11: 1 | BJ11: 22.49 | BL11: =(BI11*BJ11)-BK11 -> 22.49 | BW11: Patinho | BY11: 1.158 | BZ11: 29.99 | CB11: =(BY11*BZ11)-CA11 -> 34.72842 | CE11: Margarina | CG11: 12 | CH11: 4.99 | CJ11: =(CG11*CH11)-CI11 -> 59.88 | CM11: Pote 100ml | CO11: 1 | CP11: 139 | CQ11: 13.9 | CR11: =(CO11*CP11)-CQ11 -> 125.1 | CT11: 45097 | CU11: ITEM | CV11: MARCA | CW11: QNT. | CX11: R$ UND. | CY11: DESC. | CZ11: TOTAL | DB11: 45104 | DC11: ITEM | DD11: MARCA | DE11: QNT. | DF11: R$ UND. | DG11: DESC. | DH11: TOTAL | EA11: coca mine | EC11: 2 | ED11: 11.34 | EF11: =EC11*ED11-EE11 -> 22.68 | EI11: Abobrinha | EK11: 1 | EL11: 25 | EN11: =EK11*EL11-EM11 -> 25 | EY11: Mussarela | FA11: 4.102 | FB11: 36.9 | FD11: =(FA11*FB11)-FC11 -> 151.3638
Z12: D' Ouro minas | AA12: Pão de queijo Trad. | AC12: 2 | AD12: 12 | AF12: =(AC12*AD12)-AE12 -> 24 | AQ12: Fanta uva mine | AS12: 12 | AT12: 1.99 | AU12: 2.4 | AV12: =(AS12*AT12)-AU12 -> 21.48 | BG12: detergente | BI12: 1 | BJ12: 19.5 | BL12: =(BI12*BJ12)-BK12 -> 19.5 | BN12: 45070 | BO12: ITEM | BP12: MARCA | BQ12: QNT. | BR12: R$ UND. | BS12: DESC. | BT12: TOTAL | BW12: Bife | BY12: 8.755 | BZ12: 27.99 | CB12: =(BY12*BZ12)-CA12 -> 245.05245 | CE12: Coca mine | CG12: 72 | CH12: 1.89 | CI12: 7.2 | CJ12: =(CG12*CH12)-CI12 -> 128.88 | CM12: Tp 2500 | CO12: 1 | CP12: 156 | CQ12: 15.6 | CR12: =(CO12*CP12)-CQ12 -> 140.4 | CT12: Pão de mel | CU12: Pão de mel | CW12: 30 | CX12: 2.8 | CZ12: =(CW12*CX12)-CY12 -> 84 | DB12: Estação dos frios | DC12: Mussarela | DE12: 6.215 | DF12: 36.9 | DH12: =DE12*DF12-DG12 -> 229.3335 | DJ12: 45111 | DK12: ITEM | DL12: MARCA | DM12: QNT. | DN12: R$ UND. | DO12: DESC. | DP12: TOTAL | DR12: 45117 | DS12: ITEM | DT12: MARCA | DU12: QNT. | DV12: R$ UND. | DW12: DESC. | DX12: TOTAL | EA12: coca zero mine | EC12: 18 | ED12: 1.99 | EE12: 1.8 | EF12: =EC12*ED12-EE12 -> 34.02 | EI12: Repolho | EK12: 2 | EL12: 8 | EN12: =EK12*EL12-EM12 -> 16 | EP12: 45139 | EQ12: ITEM | ER12: MARCA | ES12: QNT. | ET12: R$ UND. | EU12: DESC. | EV12: TOTAL | EY12: Produto diverso | FA12: 1 | FB12: 8 | FD12: =(FA12*FB12)-FC12 -> 8 | FF12: 45153 | FG12: ITEM | FH12: MARCA | FI12: QNT. | FJ12: R$ UND. | FK12: DESC. | FL12: TOTAL
B13: 45014 | C13: ITEM | D13: MARCA | E13: QNT. | F13: R$ UND. | G13: DESC. | H13: TOTAL | J13: 45019 | K13: ITEM | L13: MARCA | M13: QNT. | N13: R$ UND. | O13: DESC. | P13: TOTAL | R13: 45027 | S13: ITEM | T13: MARCA | U13: QNT. | V13: R$ UND. | W13: DESC. | X13: TOTAL | AA13: Salgado Comum | AC13: 30 | AD13: 3 | AF13: =(AC13*AD13)-AE13 -> 90 | AH13: 45041 | AI13: ITEM | AJ13: MARCA | AK13: QNT. | AL13: R$ UND. | AM13: DESC. | AN13: TOTAL | AQ13: Fanta laranja mine | AS13: 12 | AT13: 1.99 | AU13: 2.4 | AV13: =(AS13*AT13)-AU13 -> 21.48 | AX13: 45053 | AY13: ITEM | AZ13: MARCA | BA13: QNT. | BB13: R$ UND. | BC13: DESC. | BD13: TOTAL | BG13: Limp Zupp | BI13: 3 | BJ13: 3.09 | BL13: =(BI13*BJ13)-BK13 -> 9.27 | BN13: Finos salgados | BO13: Salgados | BQ13: 75 | BR13: 2.75 | BT13: =(BQ13*BR13)-BS13 -> 206.25 | BV13: Crédito | BW13: TOTAL | CB13: =SUM(CB10:CB12) -> 337.61229 | CE13: Fanta Laranja mine | CG13: 24 | CH13: 1.75 | CI13: 2.4 | CJ13: =(CG13*CH13)-CI13 -> 39.6 | CL13: ? | CM13: TOTAL | CR13: =SUM(CR9:CR12) -> 322.74 | CT13: Dinheiro | CU13: TOTAL | CZ13: =SUM(CZ12:CZ12) -> 84 | DC13: Presunto | DE13: 4.1 | DF13: 23.5 | DH13: =DE13*DF13-DG13 -> 96.35 | DJ13: CEASA | DK13: Tomate | DM13: 10 | DN13: 6 | DP13: =DM13*DN13-DO13 -> 60 | DR13: estaçaõ dos frios | DS13: Mussarela | DU13: 5.174 | DV13: 36.9 | DX13: =(DU13*DV13)-DW13 -> 190.9206 | EA13: Oleo | EC13: 1 | ED13: 29.94 | EF13: =EC13*ED13-EE13 -> 29.94 | EI13: Beterraba | EK13: 1 | EL13: 40 | EN13: =EK13*EL13-EM13 -> 40 | EP13: D' Ouro minas | EQ13: Pão de queijo Trad. | ES13: 4 | ET13: 12 | EV13: =(ES13*ET13)-EU13 -> 48 | EX13: ? | EY13: TOTAL | FD13: =SUM(FD10:FD12) -> 207.6328 | FF13: Levo | FG13: Batata | FI13: 12 | FJ13: 11.4 | FL13: =(FI13*FJ13)-FK13 -> 136.8
B14: Salgados | C14: Salgados | E14: 20 | F14: 2.75 | H14: =(E14*F14)-G14 -> 55 | J14: Finos salgados | K14: Salgados | M14: 40 | N14: 2.75 | P14: =(M14*N14)-O14 -> 110 | R14: D´Ouro Minas | S14: Salgados | U14: 25 | V14: 3 | X14: =(U14*V14)-W14 -> 75 | Z14: Dinheiro | AA14: TOTAL | AF14: =SUM(AF12:AF13) -> 114 | AH14: D' Ouro minas | AI14: Pão de queijo Trad. | AK14: 4 | AL14: 12 | AN14: =(AK14*AL14)-AM14 -> 48 | AQ14: Coca mine | AS14: 8 | AT14: 11.1 | AV14: =(AS14*AT14)-AU14 -> 88.8 | AX14: Atacadão | AY14: Pão | BA14: 1 | BB14: 10.9 | BD14: =(BA14*BB14)-BC14 -> 10.9 | BG14: Hamburguer | BI14: 2 | BJ14: 37.9 | BL14: =(BI14*BJ14)-BK14 -> 75.8 | BN14: Dinheiro | BO14: TOTAL | BT14: =SUM(BT13:BT13) -> 206.25 | CE14: Sprite mine | CG14: 24 | CH14: 1.85 | CI14: 2.4 | CJ14: =(CG14*CH14)-CI14 -> 42 | DC14: Marmita redodnda | DE14: 2 | DF14: 29.9 | DH14: =DE14*DF14-DG14 -> 59.8 | DK14: Cenoura | DM14: 10 | DN14: 4 | DP14: =DM14*DN14-DO14 -> 40 | DS14: Presunto | DU14: 3.92 | DV14: 23.5 | DX14: =(DU14*DV14)-DW14 -> 92.12 | EA14: Farinha de mand | EC14: 10 | ED14: 6.99 | EE14: 5 | EF14: =EC14*ED14-EE14 -> 64.9 | EI14: Limão | EK14: 2 | EL14: 5 | EN14: =EK14*EL14-EM14 -> 10 | EQ14: Salgado Comum | ES14: 35 | ET14: 3 | EV14: =(ES14*ET14)-EU14 -> 105 | FG14: File de peito | FI14: 36 | FJ14: 11.9 | FL14: =(FI14*FJ14)-FK14 -> 428.4
B15: ? | C15: TOTAL | H15: =SUM(H14:H14) -> 55 | J15: ? | K15: TOTAL | P15: =SUM(P14:P14) -> 110 | R15: ? | S15: TOTAL | X15: =SUM(X14:X14) -> 75 | AI15: Pão de queijo Lanche | AK15: 5 | AL15: 12 | AN15: =(AK15*AL15)-AM15 -> 60 | AQ15: Coca zero mine | AS15: 4 | AT15: 10.74 | AV15: =(AS15*AT15)-AU15 -> 42.96 | AY15: Couve | BA15: 1 | BB15: 2.99 | BD15: =(BA15*BB15)-BC15 -> 2.99 | BG15: Leite | BI15: 1 | BJ15: 56.28 | BL15: =(BI15*BJ15)-BK15 -> 56.28 | BV15: 45078 | BW15: ITEM | BX15: MARCA | BY15: QNT. | BZ15: R$ UND. | CA15: DESC. | CB15: TOTAL | CE15: sprite lata | CG15: 12 | CH15: 2.69 | CI15: 3.6 | CJ15: =(CG15*CH15)-CI15 -> 28.68 | CL15: 45090 | CM15: ITEM | CN15: MARCA | CO15: QNT. | CP15: R$ UND. | CQ15: DESC. | CR15: TOTAL | CT15: 45097 | CU15: ITEM | CV15: MARCA | CW15: QNT. | CX15: R$ UND. | CY15: DESC. | CZ15: TOTAL | DC15: Garfo | DE15: 1 | DF15: 8.25 | DH15: =DE15*DF15-DG15 -> 8.25 | DK15: Chuchu | DM15: 10 | DN15: 2 | DP15: =DM15*DN15-DO15 -> 20 | DR15: Crédito | DS15: TOTAL | DX15: =SUM(DX13:DX14) -> 283.0406 | EA15: Arroz | EC15: 6 | ED15: 19.95 | EF15: =EC15*ED15-EE15 -> 119.7 | EI15: Batata | EK15: 5 | EL15: 4 | EN15: =EK15*EL15-EM15 -> 20 | EP15: Dinheiro | EQ15: TOTAL | EV15: =SUM(EV13:EV14) -> 153 | EX15: 45145 | EY15: ITEM | EZ15: MARCA | FA15: QNT. | FB15: R$ UND. | FC15: DESC. | FD15: TOTAL | FG15: Coxa S/ Coxa | FI15: 18 | FJ15: 6.9 | FL15: =(FI15*FJ15)-FK15 -> 124.2
Z16: 45033 | AA16: ITEM | AB16: MARCA | AC16: QNT. | AD16: R$ UND. | AE16: DESC. | AF16: TOTAL | AI16: Salgado Comum | AK16: 25 | AL16: 3 | AN16: =(AK16*AL16)-AM16 -> 75 | AQ16: Leite | AS16: 1 | AT16: 53.88 | AV16: =(AS16*AT16)-AU16 -> 53.88 | AY16: Abobora | BA16: 1.24 | BB16: 6.9 | BD16: =(BA16*BB16)-BC16 -> 8.556 | BG16: Feijão carioca | BI16: 20 | BJ16: 8.29 | BK16: 6 | BL16: =(BI16*BJ16)-BK16 -> 159.8 | BN16: 45070 | BO16: ITEM | BP16: MARCA | BQ16: QNT. | BR16: R$ UND. | BS16: DESC. | BT16: TOTAL | BV16: CEASA | BW16: Couve picada | BY16: 5 | BZ16: 3 | CB16: =BY16*BZ16-CA16 -> 15 | CE16: Fanta Laranja lata | CG16: 12 | CH16: 2.69 | CI16: 3.6 | CJ16: =(CG16*CH16)-CI16 -> 28.68 | CL16: Ovo | CM16: Ovo | CO16: 1 | CP16: 310.85 | CQ16: 65.85 | CR16: =(CO16*CP16)-CQ16 -> 245 | CT16: Sobradinho Carnes | CU16: Figado | CW16: 6.26 | CX16: 9.99 | CZ16: =(CW16*CX16)-CY16 -> 62.5374 | DB16: Crédito | DC16: TOTAL | DH16: =SUM(DH12:DH15) -> 393.7335 | DK16: Abobrinha | DM16: 10 | DN16: 3 | DP16: =DM16*DN16-DO16 -> 30 | EA16: Vinagre | EC16: 1 | ED16: 20.7 | EF16: =EC16*ED16-EE16 -> 20.7 | EI16: Batata doce | EK16: 1 | EL16: 30 | EN16: =EK16*EL16-EM16 -> 30 | EX16: Sobradinho Carnes | EY16: Coxa S/ coxa | FA16: 6.559 | FB16: 5.99 | FD16: =(FA16*FB16)-FC16 -> 39.28841 | FF16: ? | FG16: TOTAL | FL16: =SUM(FL13:FL15) -> 689.4
B17: 45014 | C17: ITEM | D17: MARCA | E17: QNT. | F17: R$ UND. | G17: DESC. | H17: TOTAL | J17: 45018 | K17: ITEM | L17: MARCA | M17: QNT. | N17: R$ UND. | O17: DESC. | P17: TOTAL | R17: 45027 | S17: ITEM | T17: MARCA | U17: QNT. | V17: R$ UND. | W17: DESC. | X17: TOTAL | Z17: Sobradinho Carnes | AA17: Coxão mole | AC17: 10.42 | AD17: 29.99 | AF17: =AC17*AD17-AE17 -> 312.4958 | AH17: Dinheiro | AI17: TOTAL | AN17: =SUM(AN14:AN16) -> 183 | AQ17: Oleo | AS17: 1 | AT17: 119.8 | AV17: =(AS17*AT17)-AU17 -> 119.8 | AY17: Maça | BA17: 0.54 | BB17: 7.9 | BD17: =(BA17*BB17)-BC17 -> 4.266 | BG17: Feijão preto | BI17: 1 | BJ17: 76.9 | BL17: =(BI17*BJ17)-BK17 -> 76.9 | BN17: CEASA | BO17: Tomate | BQ17: 1 | BR17: 70 | BT17: =BQ17*BR17-BS17 -> 70 | BW17: Cebolinha | BY17: 5 | BZ17: 3 | CB17: =BY17*BZ17-CA17 -> 15 | CE17: Fanta uva lata | CG17: 12 | CH17: 2.69 | CI17: 3.6 | CJ17: =(CG17*CH17)-CI17 -> 28.68 | CL17: Crédito | CM17: TOTAL | CR17: =SUM(CR16:CR16) -> 245 | CU17: Acem | CW17: 2.586 | CX17: 20.99 | CZ17: =(CW17*CX17)-CY17 -> 54.28014 | DK17: Beterraba | DM17: 5 | DN17: 4 | DP17: =DM17*DN17-DO17 -> 20 | DR17: 45117 | DS17: ITEM | DT17: MARCA | DU17: QNT. | DV17: R$ UND. | DW17: DESC. | DX17: TOTAL | EA17: Ovo | EC17: 1 | ED17: 225 | EF17: =EC17*ED17-EE17 -> 225 | EI17: Pepino | EK17: 3 | EL17: 6 | EN17: =EK17*EL17-EM17 -> 18 | EP17: 45139 | EQ17: ITEM | ER17: MARCA | ES17: QNT. | ET17: R$ UND. | EU17: DESC. | EV17: TOTAL | EY17: Figado | FA17: 4.64 | FB17: 8.99 | FD17: =(FA17*FB17)-FC17 -> 41.7136
B18: Fortes Embalagens | C18: Touca | E18: 1 | F18: 12.9 | H18: =E18*F18-G18 -> 12.9 | J18: Atacadão | K18: Cheiro verde | M18: 2 | N18: 1.99 | P18: =(M18*N18)-O18 -> 3.98 | R18: Pão de mel | S18: Pão de mel | U18: 20 | V18: 2.8 | X18: =(U18*V18)-W18 -> 56 | AA18: Fígado | AC18: 5.7 | AD18: 9.99 | AF18: =AC18*AD18-AE18 -> 56.943 | AQ18: Base culianaria | AS18: 3 | AT18: 143.68 | AV18: =(AS18*AT18)-AU18 -> 431.04 | AY18: Banana | BA18: 0.905 | BB18: 4.19 | BD18: =(BA18*BB18)-BC18 -> 3.79195 | BG18: Farinha de mand | BI18: 1 | BJ18: 59.9 | BL18: =(BI18*BJ18)-BK18 -> 59.9 | BO18: Chuchu | BQ18: 5 | BR18: 3 | BT18: =BQ18*BR18-BS18 -> 15 | BW18: Cheiro verde | BY18: 1 | BZ18: 3 | CB18: =BY18*BZ18-CA18 -> 3 | CE18: Pepsi lata | CG18: 15 | CH18: 2.05 | CI18: 1.5 | CJ18: =(CG18*CH18)-CI18 -> 29.25 | CU18: Coxão mole | CW18: 29.58 | CX18: 27.99 | CZ18: =(CW18*CX18)-CY18 -> 827.9442 | DB18: 45104 | DC18: ITEM | DD18: MARCA | DE18: QNT. | DF18: R$ UND. | DG18: DESC. | DH18: TOTAL | DK18: Batata doce | DM18: 5 | DN18: 3 | DP18: =DM18*DN18-DO18 -> 15 | DR18: Sobradinho Carnes | DS18: Pernil | DU18: 9.39 | DV18: 9.99 | DX18: =(DU18*DV18)-DW18 -> 93.8061 | DZ18: Crédito | EA18: TOTAL | EF18: =SUM(EF4:EF17) -> 702.26935 | EI18: Alface | EK18: 1 | EL18: 30 | EN18: =EK18*EL18-EM18 -> 30 | EP18: CEASA | EQ18: Cenoura | ES18: 1 | ET18: 40 | EV18: =ES18*ET18-EU18 -> 40 | EY18: Patinho | FA18: 5.594 | FB18: 26.99 | FD18: =(FA18*FB18)-FC18 -> 150.98206 | FF18: 45154 | FG18: ITEM | FH18: MARCA | FI18: QNT. | FJ18: R$ UND. | FK18: DESC. | FL18: TOTAL
C19: Toalha americana | E19: 1 | F19: 46.62 | H19: =E19*F19-G19 -> 46.62 | K19: Cenoura | M19: 10.625 | N19: 5.9 | P19: =(M19*N19)-O19 -> 62.6875 | R19: ? | S19: TOTAL | X19: =SUM(X18:X18) -> 56 | AA19: Bife | AC19: 5.192 | AD19: 31.99 | AF19: =AC19*AD19-AE19 -> 166.09208 | AH19: 45041 | AI19: ITEM | AJ19: MARCA | AK19: QNT. | AL19: R$ UND. | AM19: DESC. | AN19: TOTAL | AQ19: Batata | AS19: 2 | AT19: 153.86 | AV19: =(AS19*AT19)-AU19 -> 307.72 | AY19: Bisc. Bauducco | BA19: 1 | BB19: 6.99 | BD19: =(BA19*BB19)-BC19 -> 6.99 | BG19: Coca mine | BI19: 6 | BJ19: 11.34 | BL19: =(BI19*BJ19)-BK19 -> 68.04 | BO19: Abobrinha | BQ19: 5 | BR19: 4 | BT19: =BQ19*BR19-BS19 -> 20 | BW19: Pimenta cheiro | BY19: 1 | BZ19: 3 | CB19: =BY19*BZ19-CA19 -> 3 | CE19: Schwepes lata | CG19: 12 | CH19: 2.79 | CI19: 1.2 | CJ19: =(CG19*CH19)-CI19 -> 32.28 | CL19: 45090 | CM19: ITEM | CN19: MARCA | CO19: QNT. | CP19: R$ UND. | CQ19: DESC. | CR19: TOTAL | CT19: Crédito | CU19: TOTAL | CZ19: =SUM(CZ16:CZ18) -> 944.76174 | DB19: Levo | DC19: Batata frita | DE19: 36 | DF19: 10.99 | DH19: =(DE19*DF19)-DG19 -> 395.64 | DK19: Repolho | DM19: 2 | DN19: 8 | DP19: =DM19*DN19-DO19 -> 16 | DS19: Coxaõ mole | DU19: 35.47 | DV19: 27.99 | DX19: =(DU19*DV19)-DW19 -> 992.8053 | EI19: Pimenta cheiro | EK19: 1 | EL19: 15 | EN19: =EK19*EL19-EM19 -> 15 | EQ19: Cebola | ES19: 1 | ET19: 65 | EV19: =ES19*ET19-EU19 -> 65 | EY19: Coxao mole | FA19: 31.62 | FB19: 26.99 | FD19: =(FA19*FB19)-FC19 -> 853.4238 | FF19: Atacadão | FG19: Extrato | FI19: 2 | FJ19: 23.9 | FL19: =(FI19*FJ19)-FK19 -> 47.8
C20: Luva | E20: 1 | F20: 1.79 | H20: =E20*F20-G20 -> 1.79 | K20: Beterraba | M20: 6.295 | N20: 3.9 | P20: =(M20*N20)-O20 -> 24.5505 | Z20: ? | AA20: TOTAL | AF20: =SUM(AF17:AF19) -> 535.53088 | AH20: Fortes Embalagens | AI20: PT 102 | AK20: 1 | AL20: 38 | AN20: =(AK20*AL20)-AM20 -> 38 | AQ20: Arroz | AS20: 1 | AT20: 112.74 | AV20: =(AS20*AT20)-AU20 -> 112.74 | AY20: Bisc. Bauducco | BA20: 1 | BB20: 3.79 | BD20: =(BA20*BB20)-BC20 -> 3.79 | BG20: Coca lata | BI20: 48 | BJ20: 2.19 | BL20: =(BI20*BJ20)-BK20 -> 105.12 | BO20: Repolho Branco | BQ20: 2 | BR20: 7 | BT20: =BQ20*BR20-BS20 -> 14 | BW20: Chuchu | BY20: 5 | BZ20: 3 | CB20: =BY20*BZ20-CA20 -> 15 | CE20: Coca z 600 | CG20: 12 | CH20: 3.89 | CI20: 3.6 | CJ20: =(CG20*CH20)-CI20 -> 43.08 | CL20: CEASA | CM20: Tomate | CO20: 1 | CP20: 60 | CR20: =CO20*CP20-CQ20 -> 60 | DB20: ? | DC20: TOTAL | DH20: =SUM(DH19:DH19) -> 395.64 | DK20: Alface | DM20: 1 | DN20: 25 | DP20: =DM20*DN20-DO20 -> 25 | DS20: Figado | DU20: 6.157 | DV20: 9.89 | DX20: =(DU20*DV20)-DW20 -> 60.89273 | EI20: Alho desc | EK20: 3 | EL20: 14 | EN20: =EK20*EL20-EM20 -> 42 | EQ20: Chuchu | ES20: 1 | ET20: 25 | EV20: =ES20*ET20-EU20 -> 25 | EX20: Débito | EY20: TOTAL | FD20: =SUM(FD16:FD19) -> 1085.4079 | FG20: Batata palha | FI20: 1 | FJ20: 131.88 | FL20: =(FI20*FJ20)-FK20 -> 131.88
C21: Mascara | E21: 1 | F21: 10.99 | H21: =E21*F21-G21 -> 10.99 | K21: Ype | M21: 4 | N21: 3.29 | P21: =(M21*N21)-O21 -> 13.16 | R21: 45027 | S21: ITEM | T21: MARCA | U21: QNT. | V21: R$ UND. | W21: DESC. | X21: TOTAL | AI21: Copo 180 | AK21: 3 | AL21: 5 | AN21: =(AK21*AL21)-AM21 -> 15 | AQ21: Feijão | AS21: 20 | AT21: 7.79 | AV21: =(AS21*AT21)-AU21 -> 155.8 | AY21: Algodão | BA21: 1 | BB21: 5.69 | BD21: =(BA21*BB21)-BC21 -> 5.69 | BG21: Fanta Laranja lata | BI21: 1 | BJ21: 14.34 | BL21: =(BI21*BJ21)-BK21 -> 14.34 | BO21: Repolho roco | BQ21: 1 | BR21: 8 | BT21: =BQ21*BR21-BS21 -> 8 | BW21: Abobrinha | BY21: 5 | BZ21: 4 | CB21: =BY21*BZ21-CA21 -> 20 | CE21: Coca 600 | CG21: 45 | CH21: 3.95 | CJ21: =(CG21*CH21)-CI21 -> 177.75 | CM21: Cenoura | CO21: 1 | CP21: 40 | CR21: =CO21*CP21-CQ21 -> 40 | CT21: 45097 | CU21: ITEM | CV21: MARCA | CW21: QNT. | CX21: R$ UND. | CY21: DESC. | CZ21: TOTAL | DK21: Cebolinha | DM21: 10 | DN21: 2 | DP21: =DM21*DN21-DO21 -> 20 | DR21: Crédito | DS21: TOTAL | DX21: =SUM(DX18:DX20) -> 1147.5041 | DZ21: 45126 | EA21: ITEM | EB21: MARCA | EC21: QNT. | ED21: R$ UND. | EE21: DESC. | EF21: TOTAL | EI21: Cebolinha | EK21: 5 | EL21: 3 | EN21: =EK21*EL21-EM21 -> 15 | EQ21: Repolho | ES21: 2 | ET21: 8 | EV21: =ES21*ET21-EU21 -> 16 | FG21: Tempero Arisco | FI21: 5 | FJ21: 4.99 | FK21: 2.5 | FL21: =(FI21*FJ21)-FK21 -> 22.45
C22: Saco | E22: 1 | F22: 22 | H22: =E22*F22-G22 -> 22 | K22: Sabão Guarani | M22: 3 | N22: 7.99 | P22: =(M22*N22)-O22 -> 23.97 | R22: Ceasa | S22: Abobora | U22: 1 | V22: 60 | X22: =U22*V22-W22 -> 60 | Z22: 45033 | AA22: ITEM | AB22: MARCA | AC22: QNT. | AD22: R$ UND. | AE22: DESC. | AF22: TOTAL | AI22: Toalha americana | AK22: 3 | AL22: 25 | AN22: =(AK22*AL22)-AM22 -> 75 | AP22: Crédito | AQ22: TOTAL | AV22: =SUM(AV4:AV21) -> 1565.93 | AY22: cotonete | BA22: 1 | BB22: 19.9 | BD22: =(BA22*BB22)-BC22 -> 19.9 | BG22: Schwepes lata | BI22: 1 | BJ22: 16.74 | BL22: =(BI22*BJ22)-BK22 -> 16.74 | BO22: Acelga | BQ22: 2 | BR22: 4 | BT22: =BQ22*BR22-BS22 -> 8 | BW22: Cenoura | BY22: 5 | BZ22: 5 | CB22: =BY22*BZ22-CA22 -> 25 | CE22: Guarana 600 | CG22: 12 | CH22: 3.89 | CI22: 3.6 | CJ22: =(CG22*CH22)-CI22 -> 43.08 | CM22: Chuchu | CO22: 1 | CP22: 25 | CR22: =CO22*CP22-CQ22 -> 25 | CT22: D' Ouro minas | CU22: Pão de queijo Trad. | CW22: 3 | CX22: 12 | CZ22: =(CW22*CX22)-CY22 -> 36 | DB22: 45105 | DC22: ITEM | DD22: MARCA | DE22: QNT. | DF22: R$ UND. | DG22: DESC. | DH22: TOTAL | DK22: Couve | DM22: 5 | DN22: 3 | DP22: =DM22*DN22-DO22 -> 15 | DZ22: Friatto | EA22: Linguiça de frango | EC22: 20 | ED22: 14.99 | EF22: =(EC22*ED22)-EE22 -> 299.8 | EI22: Cheiro verde | EK22: 2 | EL22: 3 | EN22: =EK22*EL22-EM22 -> 6 | EQ22: Beterraba | ES22: 1 | ET22: 35 | EV22: =ES22*ET22-EU22 -> 35 | EX22: 45145 | EY22: ITEM | EZ22: MARCA | FA22: QNT. | FB22: R$ UND. | FC22: DESC. | FD22: TOTAL | FG22: Sal | FI22: 2 | FJ22: 1.79 | FL22: =(FI22*FJ22)-FK22 -> 3.58
C23: Canudo | E23: 1 | F23: 12.51 | H23: =E23*F23-G23 -> 12.51 | K23: Limp ZUPP | M23: 3 | N23: 2.9 | O23: 0.33 | P23: =(M23*N23)-O23 -> 8.37 | U23: 1 | V23: 30 | X23: =U23*V23-W23 -> 30 | Z23: Atacadão | AA23: Acelga | AC23: 2 | AD23: 4.15 | AF23: =(AC23*AD23)-AE23 -> 8.3 | AI23: Mascara | AK23: 1 | AL23: 10 | AN23: =(AK23*AL23)-AM23 -> 10 | AY23: Requeijão | BA23: 1 | BB23: 7.9 | BD23: =(BA23*BB23)-BC23 -> 7.9 | BG23: Sprite lata | BI23: 6 | BJ23: 2.49 | BK23: 0.6 | BL23: =(BI23*BJ23)-BK23 -> 14.34 | BO23: Cebolinha | BQ23: 10 | BR23: 3 | BT23: =BQ23*BR23-BS23 -> 30 | BW23: Beterraba | BY23: 5 | BZ23: 4 | CB23: =BY23*BZ23-CA23 -> 20 | CE23: Guarana 1.5L | CG23: 6 | CH23: 4.69 | CI23: 1.2 | CJ23: =(CG23*CH23)-CI23 -> 26.94 | CM23: Abobrinha | CO23: 1 | CP23: 30 | CR23: =CO23*CP23-CQ23 -> 30 | CU23: Pão de queijo Lanche | CW23: 5 | CX23: 12 | CZ23: =(CW23*CX23)-CY23 -> 60 | DB23: Friato | DC23: Linguiça de frango | DE23: 20 | DF23: 14.99 | DH23: =(DE23*DF23)-DG23 -> 299.8 | DK23: Alho desc | DM23: 2 | DN23: 12 | DP23: =DM23*DN23-DO23 -> 24 | DR23: 45118 | DS23: ITEM | DT23: MARCA | DU23: QNT. | DV23: R$ UND. | DW23: DESC. | DX23: TOTAL | DZ23: ? | EA23: TOTAL | EF23: =SUM(EF22:EF22) -> 299.8 | EH23: dinheiro | EI23: TOTAL | EN23: =SUM(EN8:EN22) -> 387 | EQ23: Limão | ES23: 2 | ET23: 5 | EV23: =ES23*ET23-EU23 -> 10 | EX23: Fortes Embalagens | EY23: Mascara | FA23: 2 | FB23: 9.99 | FC23: 4 | FD23: =(FA23*FB23)-FC23 -> 15.98 | FG23: Pão de forma | FI23: 4 | FJ23: 5.99 | FL23: =(FI23*FJ23)-FK23 -> 23.96
C24: PT-102 | E24: 1 | F24: 74 | H24: =E24*F24-G24 -> 74 | K24: Alcool | M24: 1 | N24: 6.79 | P24: =(M24*N24)-O24 -> 6.79 | S24: Chuchu | U24: 1 | V24: 50 | X24: =U24*V24-W24 -> 50 | AA24: Cheiro verde | AC24: 3 | AD24: 1.89 | AF24: =(AC24*AD24)-AE24 -> 5.67 | AI24: Garfo | AK24: 3 | AL24: 2.3 | AN24: =(AK24*AL24)-AM24 -> 6.9 | AP24: 45049 | AQ24: ITEM | AR24: MARCA | AS24: QNT. | AT24: R$ UND. | AU24: DESC. | AV24: TOTAL | AY24: Paçoca | BA24: 1 | BB24: 8.49 | BD24: =(BA24*BB24)-BC24 -> 8.49 | BG24: Coca mine | BI24: 6 | BJ24: 2.39 | BK24: 0.6 | BL24: =(BI24*BJ24)-BK24 -> 13.74 | BO24: Couve | BQ24: 10 | BR24: 3 | BT24: =BQ24*BR24-BS24 -> 30 | BW24: Laranja | BY24: 1 | BZ24: 40 | CB24: =BY24*BZ24-CA24 -> 40 | CE24: Coca 2L | CG24: 9 | CH24: 7.29 | CJ24: =(CG24*CH24)-CI24 -> 65.61 | CM24: Beterraba | CO24: 5 | CP24: 4 | CR24: =CO24*CP24-CQ24 -> 20 | CU24: Salgado Comum | CW24: 30 | CX24: 3 | CZ24: =(CW24*CX24)-CY24 -> 90 | DB24: ? | DC24: TOTAL | DH24: =SUM(DH23:DH23) -> 299.8 | DK24: Batata | DM24: 5 | DN24: 5 | DP24: =DM24*DN24-DO24 -> 25 | DR24: Atacadão | DS24: Ovo | DU24: 1 | DV24: 219 | DW24: 20 | DX24: =(DU24*DV24)-DW24 -> 199 | EQ24: Batata | ES24: 5 | ET24: 4 | EV24: =ES24*ET24-EU24 -> 20 | EY24: Papel Branco | FA24: 1 | FB24: 17.9 | FC24: 5 | FD24: =(FA24*FB24)-FC24 -> 12.9 | FG24: Oleo | FI24: 18 | FJ24: 5.29 | FK24: 16.02 | FL24: =(FI24*FJ24)-FK24 -> 79.2
B25: ? | C25: TOTAL | H25: =SUM(H18:H24) -> 180.81 | K25: Detergente | M25: 4 | N25: 2.39 | P25: =(M25*N25)-O25 -> 9.56 | S25: Cenoura | U25: 1 | V25: 60 | X25: =U25*V25-W25 -> 60 | AA25: Repolho | AC25: 5.525 | AD25: 3.99 | AE25: 6.07 | AF25: =(AC25*AD25)-AE25 -> 15.97475 | AI25: Faca | AK25: 2 | AL25: 70 | AN25: =(AK25*AL25)-AM25 -> 140 | AP25: Natural Brasil | AQ25: Barra acerola | AS25: 5 | AT25: 11.5 | AV25: =(AS25*AT25)-AU25 -> 57.5 | AY25: bisc. Maisena | BA25: 5 | BB25: 5.49 | BC25: 5 | BD25: =(BA25*BB25)-BC25 -> 22.45 | BF25: Crédito | BG25: TOTAL | BL25: =SUM(BL8:BL24) -> 751.18 | BO25: Alho desc | BQ25: 3 | BR25: 12 | BT25: =BQ25*BR25-BS25 -> 36 | BW25: Limão | BY25: 2 | BZ25: 3 | CB25: =BY25*BZ25-CA25 -> 6 | CE25: Coca z 2L | CG25: 9 | CH25: 6.79 | CI25: 2.7 | CJ25: =(CG25*CH25)-CI25 -> 58.41 | CM25: Batata doce | CO25: 5 | CP25: 4 | CR25: =CO25*CP25-CQ25 -> 20 | CT25: Dinheiro | CU25: TOTAL | CZ25: =SUM(CZ22:CZ24) -> 186 | DK25: Limão | DM25: 2.5 | DN25: 3 | DP25: =DM25*DN25-DO25 -> 7.5 | DS25: Cebolinha | DU25: 4 | DV25: 1.95 | DX25: =(DU25*DV25)-DW25 -> 7.8 | DZ25: 45126 | EA25: ITEM | EB25: MARCA | EC25: QNT. | ED25: R$ UND. | EE25: DESC. | EF25: TOTAL | EH25: 45132 | EI25: ITEM | EJ25: MARCA | EK25: QNT. | EL25: R$ UND. | EM25: DESC. | EN25: TOTAL | EQ25: Batata doce | ES25: 5 | ET25: 4 | EV25: =ES25*ET25-EU25 -> 20 | EY25: Papel Pardo | FA25: 1 | FB25: 15.9 | FC25: 4 | FD25: =(FA25*FB25)-FC25 -> 11.9 | FG25: Coca mine | FI25: 2 | FJ25: 11.34 | FL25: =(FI25*FJ25)-FK25 -> 22.68
K26: Bombril | M26: 5 | N26: 2.56 | P26: =(M26*N26)-O26 -> 12.8 | S26: Batata doce | U26: 1 | V26: 35 | X26: =U26*V26-W26 -> 35 | AA26: Limão | AC26: 1.29 | AD26: 2.99 | AE26: 1.29 | AF26: =(AC26*AD26)-AE26 -> 2.5671 | AI26: Garfo forte | AK26: 1 | AL26: 80 | AN26: =(AK26*AL26)-AM26 -> 80 | AQ26: Barra cupuaçu | AS26: 5 | AT26: 9.6 | AV26: =(AS26*AT26)-AU26 -> 48 | AY26: Bisc. Passatempo | BA26: 7 | BB26: 2.99 | BC26: 2.8 | BD26: =(BA26*BB26)-BC26 -> 18.13 | BO26: Laranja | BQ26: 1 | BR26: 40 | BT26: =BQ26*BR26-BS26 -> 40 | BW26: Repolho | BY26: 2 | BZ26: 8 | CB26: =BY26*BZ26-CA26 -> 16 | CE26: Feijão carioca | CG26: 10 | CH26: 6.99 | CJ26: =(CG26*CH26)-CI26 -> 69.9 | CM26: Repolho | CO26: 2 | CP26: 8 | CR26: =CO26*CP26-CQ26 -> 16 | DB26: 45105 | DC26: ITEM | DD26: MARCA | DE26: QNT. | DF26: R$ UND. | DG26: DESC. | DH26: TOTAL | DK26: Banana | DM26: 1 | DN26: 50 | DP26: =DM26*DN26-DO26 -> 50 | DS26: Tomate | DU26: 5.305 | DV26: 6.9 | DX26: =(DU26*DV26)-DW26 -> 36.6045 | DZ26: Sobradinho Carnes | EA26: Pernil | EC26: 15.225 | ED26: 14.99 | EF26: =(EC26*ED26)-EE26 -> 228.22275 | EH26: Levo | EI26: Batata | EK26: 12 | EL26: 10.99 | EN26: =(EK26*EL26)-EM26 -> 131.88 | EQ26: Pepino | ES26: 3 | ET26: 6 | EV26: =ES26*ET26-EU26 -> 18 | EY26: Papel Pardo | FA26: 2 | FB26: 24.9 | FC26: 2.8 | FD26: =(FA26*FB26)-FC26 -> 47 | FG26: Coca lata | FI26: 1 | FJ26: 28.2 | FL26: =(FI26*FJ26)-FK26 -> 28.2
